Workbook
Name DV_NAMED_LIST_RANGES_0: #REF!
Name DV_NAMED_LIST_RANGES_1: #REF!
Name DV_NAMED_LIST_RANGES_2: #REF!
Name DV_NAMED_LIST_RANGES_3: #REF!
Name DV_NAMED_LIST_RANGES_4: #REF!
Name DV_NAMED_LIST_RANGES_5: #REF!
Name DV_NAMED_LIST_RANGES_6: #REF!

Sheet Instructions
A1: Fri Feb 5 09:22:50 2021 | D1: 1612279831 | E1: 10 | F1: Instructions: en_US
A2: Bids-2021-02-05 09.22AM
A3: Mars - Mars Global Ocean Tender 2021
A4: Item Type | B4: Filters Applied | C4: Items
A5: Lanes | B5: (none) | C5: 1405 of 1405
A7: Instructions
A9: Instructions
A11: It is recommended that you do not wait until the last day of bidding
A12: to first upload your bid sheet. A test upload may help you identify
A13: any mistakes you are making early in the process and reduce the risk of
A14: errors when submitting your bids before the deadline.
A16: BID Upload:
A18: The buyer in this event has provided bidders with additional rate sheets
A19: to facilitate and supplement line item bidding. When providing bidding
A20: information, please use the provided tabs and follow any inserted buyer
A21: instructions. You will see your entered values reflected in the line
A22: item bids on the Item tabs. This is informational only, bids should be
... A33: that are saved in our system.

Sheet BID_Lanes
A1: Item ID | B1: Lane ID | C1: Item Quantity | D1: Item Code | E1: Jaggaer Identifier | F1: Route Status | G1: Movement Type | H1: Container Type | I1: From Town | J1: Preferred Port/Ramp/ICD of Loading | K1: Origin Zip Code | L1: From Country | M1: From Region | N1: Origin BAF Region | O1: To Town | P1: Preferred Port/Ramp/ICD Discharge | Q1: Destination Zip Code | R1: To Country | S1: To Region | T1: Destination BAF Region | U1: Commodity | V1: Incoterm | W1: Freight terms - prepaid or collect | X1: Where is DTHC to be paid? | Y1: Gen-set needed for Origin inland transport | Z1: Gen-set needed for Destination inland transport | AA1: Multi-modal precarriage allowed? | AB1: Containers | AC1: Prepopulated Weekly Volume | AD1: If weekly volume is seasonal,Select Yes and include % split in the next columns | AE1: Q3'21 ( July'21- Sep'21) | AF1: Q4'21 ( Oct'21- Dec'21) | AG1: Q1'22 ( Jan'22- Mar'22) | AH1: Q2'22 ( Apr'22- Jun'22) | AI1: Is OIC MICH? Yes/No | AJ1: Port of LOADING demurrage Carriers Quote in calendar days | AK1: Port of LOADING detention Carriers Quote in calendar days | AL1: Port of LOADING combined demurrage/ detention Quote in calendar days | AM1: Specific Requirements at Origin | AN1: Port of DISCHARGE demurrage Carriers Quote in calendar days | AO1: Port of DISCHARGE detention Carriers Quote in calendar days | AP1: Port of DISCHARGE combined demurrage/ detention Quote in calendar days | AQ1: Specific Requirements at Destination | AR1: BAF Trade Coefficient | AS1: Bid Currency* | AT1: OIC Per Load (USD) - 6 months validity | AU1: OTHC Per Load (USD) - 6 months validity | AV1: Ocean Freight Per Load (USD) - 6 months validity | AW1: Bunker element - BAF (USD) - 6 months validity | AX1: DTHC Per Load (USD) - 6 months validity | AY1: DIC Per Load (USD) - 6 months validity | AZ1: Total Load Price - Port - Port (USD) - 6 months validity | BA1: Total Load Price incl inland charges (USD) - 6 months validity | BB1: OIC Per Load (USD) - 12 months validity | BC1: OTHC Per Load (USD)- 12 months validity | BD1: Ocean Freight Per Load (USD)- 12 months validity | BE1: Bunker element - BAF (USD)- 12 months validity | BF1: DTHC Per Load (USD) - 12 months validity | BG1: DIC Per Load (USD)- 12 months validity | BH1: Total Load Price - Port - Port (USD)- 12 months validity | BI1: Total Load Price incl inland charges (USD)- 12 months validity | BJ1: Service offered for this lane | BK1: Port of loading (if different to preferred) | BL1: Port of discharge (if different to preferred) | BM1: Direct / Indirect service (Please use Drop Down) | BN1: Trans Shipment Ports | BO1: Containers Per Voyage | BP1: Voyages Per Month | BQ1: How is destination port terminal storage invoiced (carrier or terminal?) | BR1: Precarriage transit time in days (Enter Whole Number) | BS1: Port-port transit time in days (Enter Whole Number) | BT1: Oncarriage transit time in days (Enter Whole Number) | BU1: Total Transit Time in Days | BV1: Max Net Weight Per Load in tons | BW1: Mode of transport offered for precarriage (Please Use Drop Down) | BX1: Mode of transport offered for oncarriage (Please Use Drop Down) | BY1: Comments by carriers per bid | BZ1: Can all dest. charges(includ. local port dues,taxes etc)be prepaid if required? | CA1: No of free hours offered for loading at origin | CB1: Hourly rate after waiting time exceeded at orgin | CC1: No of free hours offered for unloading at destination | CD1: Hourly rate after waiting time exceeded at destination | CE1: POL DEMURRAGE Carriers Quote in calendar days | CF1: POL DETENTION Carriers Quote in calendar days | CG1: POL COMBINED demurrage/ detention Quote in calendar days | CH1: POL post freetime Demurrage charge per day (USD) | CI1: POL post freetime Detention charge per day (USD) | CJ1: POL Combined post freetime charge per day (USD) | CK1: POD DEMURRAGE Carriers Quote in calendar days | CL1: POD DETENTION Carriers Quote in calendar days | CM1: POD COMBINED demurrage/ detention Quote in calendar days | CN1: POD post freetime Demurrage charge per day (USD) | CO1: POD post freetime Detention charge per day (USD) | CP1: POD Combined post freetime charge per day (USD) | CQ1: Delete | CR1: Item Type ID: 1 | CS1: sheet name: Lanes
A2: 1406 | B2: 1089 | C2: 1 | D2: 101 | E2: 101 | F2: Existing | G2: Port to Port | H2: 20' DV | I2: Makassar | J2: Makassar | L2: Indonesia | M2: APAC | N2: Far East | O2: Xingang | P2: Xingang/Tianjin | R2: China | S2: APAC | T2: Far East | U2: Cocoa Liquor | V2: CFR | W2: Prepaid | X2: Sending Unit | AA2: Yes | AB2: 60 | AC2: 2 | AD2: No | AE2: 0.25 | AF2: 0.25 | AG2: 0.25 | AH2: 0.25 | AI2: No | AJ2: 14 | AK2: 14 | AL2: 0 | AN2: 14 | AO2: 10 | AP2: 24 | AR2: 0.1 | AS2: USD | AT2: =IF(ISBLANK(Lanes!AO2),"",ROUND(Lanes!AO2,2)) | AU2: =IF(ISBLANK(Lanes!AP2),"",ROUND(Lanes!AP2,2)) | AV2: =IF(ISBLANK(Lanes!AQ2),"",ROUND(Lanes!AQ2,2)) | AW2: =IF(ISBLANK(Lanes!AP2),"",ROUND(Lanes!AR2,2)) | AX2: =IF(ISBLANK(Lanes!AS2),"",ROUND(Lanes!AS2,2)) | AY2: =IF(ISBLANK(Lanes!AT2),"",ROUND(Lanes!AT2,2)) | AZ2: =IF(ISBLANK(Lanes!AP2),"",ROUND(Lanes!AU2,2)) | BA2: =IF(ISBLANK(Lanes!AP2),"",ROUND(Lanes!AV2,2)) | BB2: =IF(ISBLANK(Lanes!AW2),"",ROUND(Lanes!AW2,2)) | BC2: =IF(ISBLANK(Lanes!AX2),"",ROUND(Lanes!AX2,2)) | BD2: =IF(ISBLANK(Lanes!AY2),"",ROUND(Lanes!AY2,2)) | BE2: =IF(ISBLANK(Lanes!AX2),"",ROUND(Lanes!AZ2,2)) | BF2: =IF(ISBLANK(Lanes!BA2),"",ROUND(Lanes!BA2,2)) | BG2: =IF(ISBLANK(Lanes!BB2),"",ROUND(Lanes!BB2,2)) | BH2: =IF(ISBLANK(Lanes!AX2),"",ROUND(Lanes!BC2,2)) | BI2: =IF(ISBLANK(Lanes!AX2),"",ROUND(Lanes!BD2,2)) | BJ2: =IF(ISBLANK(Lanes!BE2),"",Lanes!BE2) | BK2: =IF(ISBLANK(Lanes!BF2),"",Lanes!BF2) | BL2: =IF(ISBLANK(Lanes!BG2),"",Lanes!BG2) | BM2: =IF(ISBLANK(Lanes!BH2),"",Lanes!BH2) | BN2: =IF(ISBLANK(Lanes!BI2),"",Lanes!BI2) | BO2: =IF(ISBLANK(Lanes!BJ2),"",Lanes!BJ2) | BP2: =IF(ISBLANK(Lanes!BK2),"",Lanes!BK2) | BQ2: =IF(ISBLANK(Lanes!BL2),"",Lanes!BL2) | BR2: =IF(ISBLANK(Lanes!BM2),"",ROUND(Lanes!BM2,0)) | BS2: =IF(ISBLANK(Lanes!BN2),"",ROUND(Lanes!BN2,0)) | BT2: =IF(ISBLANK(Lanes!BO2),"",ROUND(Lanes!BO2,0)) | BU2: =IF(ISBLANK(Lanes!BN2),"",ROUND(Lanes!BP2,0)) | BV2: =IF(ISBLANK(Lanes!BQ2),"",ROUND(Lanes!BQ2,1)) | BW2: =IF(ISBLANK(Lanes!BR2),"",Lanes!BR2) | BX2: =IF(ISBLANK(Lanes!BS2),"",Lanes!BS2) | BY2: =IF(ISBLANK(Lanes!BT2),"",Lanes!BT2) | BZ2: =IF(ISBLANK(Lanes!BU2),"",Lanes!BU2) | CA2: =IF(ISBLANK(Lanes!BV2),"",ROUND(Lanes!BV2,1)) | CB2: =IF(ISBLANK(Lanes!BW2),"",ROUND(Lanes!BW2,2)) | CC2: =IF(ISBLANK(Lanes!BX2),"",ROUND(Lanes!BX2,1)) | CD2: =IF(ISBLANK(Lanes!BY2),"",ROUND(Lanes!BY2,2)) | CE2: =IF(ISBLANK(Lanes!BZ2),"",ROUND(Lanes!BZ2,0)) | CF2: =IF(ISBLANK(Lanes!CA2),"",ROUND(Lanes!CA2,0)) | CG2: =IF(ISBLANK(Lanes!CB2),"",ROUND(Lanes!CB2,0)) | CH2: =IF(ISBLANK(Lanes!CC2),"",ROUND(Lanes!CC2,2)) | CI2: =IF(ISBLANK(Lanes!CD2),"",ROUND(Lanes!CD2,2)) | CJ2: =IF(ISBLANK(Lanes!CE2),"",ROUND(Lanes!CE2,2)) | CK2: =IF(ISBLANK(Lanes!CF2),"",ROUND(Lanes!CF2,0)) | CL2: =IF(ISBLANK(Lanes!CG2),"",ROUND(Lanes!CG2,0)) | CM2: =IF(ISBLANK(Lanes!CH2),"",ROUND(Lanes!CH2,0)) | CN2: =IF(ISBLANK(Lanes!CI2),"",ROUND(Lanes!CI2,2)) | CO2: =IF(ISBLANK(Lanes!CJ2),"",ROUND(Lanes!CJ2,2)) | CP2: =IF(ISBLANK(Lanes!CK2),"",ROUND(Lanes!CK2,2)) | CQ2: =IF(ISBLANK(Lanes!CL2),"","delete")
A3: 1407 | B3: 1090 | C3: 1 | D3: 102 | E3: 102 | F3: Existing | G3: Port to Port | H3: 20' DV | I3: Makassar | J3: Makassar | L3: Indonesia | M3: APAC | N3: Far East | O3: Shanghai | P3: Shanghai | R3: China | S3: APAC | T3: Far East | U3: Cocoa Liquor | V3: CFR | W3: Prepaid | X3: Sending Unit | AA3: Yes | AB3: 140 | AC3: 3 | AD3: No | AE3: 0.25 | AF3: 0.25 | AG3: 0.25 | AH3: 0.25 | AI3: No | AJ3: 14 | AK3: 14 | AL3: 0 | AN3: 0 | AO3: 0 | AP3: 21 | AR3: 0.1 | AS3: USD | AT3: =IF(ISBLANK(Lanes!AO3),"",ROUND(Lanes!AO3,2)) | AU3: =IF(ISBLANK(Lanes!AP3),"",ROUND(Lanes!AP3,2)) | AV3: =IF(ISBLANK(Lanes!AQ3),"",ROUND(Lanes!AQ3,2)) | AW3: =IF(ISBLANK(Lanes!AP3),"",ROUND(Lanes!AR3,2)) | AX3: =IF(ISBLANK(Lanes!AS3),"",ROUND(Lanes!AS3,2)) | AY3: =IF(ISBLANK(Lanes!AT3),"",ROUND(Lanes!AT3,2)) | AZ3: =IF(ISBLANK(Lanes!AP3),"",ROUND(Lanes!AU3,2)) | BA3: =IF(ISBLANK(Lanes!AP3),"",ROUND(Lanes!AV3,2)) | BB3: =IF(ISBLANK(Lanes!AW3),"",ROUND(Lanes!AW3,2)) | BC3: =IF(ISBLANK(Lanes!AX3),"",ROUND(Lanes!AX3,2)) | BD3: =IF(ISBLANK(Lanes!AY3),"",ROUND(Lanes!AY3,2)) | BE3: =IF(ISBLANK(Lanes!AX3),"",ROUND(Lanes!AZ3,2)) | BF3: =IF(ISBLANK(Lanes!BA3),"",ROUND(Lanes!BA3,2)) | BG3: =IF(ISBLANK(Lanes!BB3),"",ROUND(Lanes!BB3,2)) | BH3: =IF(ISBLANK(Lanes!AX3),"",ROUND(Lanes!BC3,2)) | BI3: =IF(ISBLANK(Lanes!AX3),"",ROUND(Lanes!BD3,2)) | BJ3: =IF(ISBLANK(Lanes!BE3),"",Lanes!BE3) | BK3: =IF(ISBLANK(Lanes!BF3),"",Lanes!BF3) | BL3: =IF(ISBLANK(Lanes!BG3),"",Lanes!BG3) | BM3: =IF(ISBLANK(Lanes!BH3),"",Lanes!BH3) | BN3: =IF(ISBLANK(Lanes!BI3),"",Lanes!BI3) | BO3: =IF(ISBLANK(Lanes!BJ3),"",Lanes!BJ3) | BP3: =IF(ISBLANK(Lanes!BK3),"",Lanes!BK3) | BQ3: =IF(ISBLANK(Lanes!BL3),"",Lanes!BL3) | BR3: =IF(ISBLANK(Lanes!BM3),"",ROUND(Lanes!BM3,0)) | BS3: =IF(ISBLANK(Lanes!BN3),"",ROUND(Lanes!BN3,0)) | BT3: =IF(ISBLANK(Lanes!BO3),"",ROUND(Lanes!BO3,0)) | BU3: =IF(ISBLANK(Lanes!BN3),"",ROUND(Lanes!BP3,0)) | BV3: =IF(ISBLANK(Lanes!BQ3),"",ROUND(Lanes!BQ3,1)) | BW3: =IF(ISBLANK(Lanes!BR3),"",Lanes!BR3) | BX3: =IF(ISBLANK(Lanes!BS3),"",Lanes!BS3) | BY3: =IF(ISBLANK(Lanes!BT3),"",Lanes!BT3) | BZ3: =IF(ISBLANK(Lanes!BU3),"",Lanes!BU3) | CA3: =IF(ISBLANK(Lanes!BV3),"",ROUND(Lanes!BV3,1)) | CB3: =IF(ISBLANK(Lanes!BW3),"",ROUND(Lanes!BW3,2)) | CC3: =IF(ISBLANK(Lanes!BX3),"",ROUND(Lanes!BX3,1)) | CD3: =IF(ISBLANK(Lanes!BY3),"",ROUND(Lanes!BY3,2)) | CE3: =IF(ISBLANK(Lanes!BZ3),"",ROUND(Lanes!BZ3,0)) | CF3: =IF(ISBLANK(Lanes!CA3),"",ROUND(Lanes!CA3,0)) | CG3: =IF(ISBLANK(Lanes!CB3),"",ROUND(Lanes!CB3,0)) | CH3: =IF(ISBLANK(Lanes!CC3),"",ROUND(Lanes!CC3,2)) | CI3: =IF(ISBLANK(Lanes!CD3),"",ROUND(Lanes!CD3,2)) | CJ3: =IF(ISBLANK(Lanes!CE3),"",ROUND(Lanes!CE3,2)) | CK3: =IF(ISBLANK(Lanes!CF3),"",ROUND(Lanes!CF3,0)) | CL3: =IF(ISBLANK(Lanes!CG3),"",ROUND(Lanes!CG3,0)) | CM3: =IF(ISBLANK(Lanes!CH3),"",ROUND(Lanes!CH3,0)) | CN3: =IF(ISBLANK(Lanes!CI3),"",ROUND(Lanes!CI3,2)) | CO3: =IF(ISBLANK(Lanes!CJ3),"",ROUND(Lanes!CJ3,2)) | CP3: =IF(ISBLANK(Lanes!CK3),"",ROUND(Lanes!CK3,2)) | CQ3: =IF(ISBLANK(Lanes!CL3),"","delete")
A4: 1408 | B4: 1093 | C4: 1 | D4: 103 | E4: 103 | F4: Existing | G4: Port to Port | H4: 20' RF | I4: Shanghai | J4: Shanghai | L4: China | M4: APAC | N4: Far East | O4: Bangkok | P4: Bangkok (Pat/Lat Krabang/Laem Chabang) | R4: Thailand | S4: APAC | T4: Far East | U4: Confectionary | V4: FOB | W4: Collect | X4: Receiving Unit | AA4: Yes | AB4: 10 | AC4: 1 | AD4: No | AE4: 0.25 | AF4: 0.25 | AG4: 0.25 | AH4: 0.25 | AI4: No | AJ4: 10 | AK4: 7 | AL4: 17 | AN4: 10 | AO4: 7 | AP4: 17 | AR4: 0.1 | AS4: USD | AT4: =IF(ISBLANK(Lanes!AO4),"",ROUND(Lanes!AO4,2)) | AU4: =IF(ISBLANK(Lanes!AP4),"",ROUND(Lanes!AP4,2)) | AV4: =IF(ISBLANK(Lanes!AQ4),"",ROUND(Lanes!AQ4,2)) | AW4: =IF(ISBLANK(Lanes!AP4),"",ROUND(Lanes!AR4,2)) | AX4: =IF(ISBLANK(Lanes!AS4),"",ROUND(Lanes!AS4,2)) | AY4: =IF(ISBLANK(Lanes!AT4),"",ROUND(Lanes!AT4,2)) | AZ4: =IF(ISBLANK(Lanes!AP4),"",ROUND(Lanes!AU4,2)) | BA4: =IF(ISBLANK(Lanes!AP4),"",ROUND(Lanes!AV4,2)) | BB4: =IF(ISBLANK(Lanes!AW4),"",ROUND(Lanes!AW4,2)) | BC4: =IF(ISBLANK(Lanes!AX4),"",ROUND(Lanes!AX4,2)) | BD4: =IF(ISBLANK(Lanes!AY4),"",ROUND(Lanes!AY4,2)) | BE4: =IF(ISBLANK(Lanes!AX4),"",ROUND(Lanes!AZ4,2)) | BF4: =IF(ISBLANK(Lanes!BA4),"",ROUND(Lanes!BA4,2)) | BG4: =IF(ISBLANK(Lanes!BB4),"",ROUND(Lanes!BB4,2)) | BH4: =IF(ISBLANK(Lanes!AX4),"",ROUND(Lanes!BC4,2)) | BI4: =IF(ISBLANK(Lanes!AX4),"",ROUND(Lanes!BD4,2)) | BJ4: =IF(ISBLANK(Lanes!BE4),"",Lanes!BE4) | BK4: =IF(ISBLANK(Lanes!BF4),"",Lanes!BF4) | BL4: =IF(ISBLANK(Lanes!BG4),"",Lanes!BG4) | BM4: =IF(ISBLANK(Lanes!BH4),"",Lanes!BH4) | BN4: =IF(ISBLANK(Lanes!BI4),"",Lanes!BI4) | BO4: =IF(ISBLANK(Lanes!BJ4),"",Lanes!BJ4) | BP4: =IF(ISBLANK(Lanes!BK4),"",Lanes!BK4) | BQ4: =IF(ISBLANK(Lanes!BL4),"",Lanes!BL4) | BR4: =IF(ISBLANK(Lanes!BM4),"",ROUND(Lanes!BM4,0)) | BS4: =IF(ISBLANK(Lanes!BN4),"",ROUND(Lanes!BN4,0)) | BT4: =IF(ISBLANK(Lanes!BO4),"",ROUND(Lanes!BO4,0)) | BU4: =IF(ISBLANK(Lanes!BN4),"",ROUND(Lanes!BP4,0)) | BV4: =IF(ISBLANK(Lanes!BQ4),"",ROUND(Lanes!BQ4,1)) | BW4: =IF(ISBLANK(Lanes!BR4),"",Lanes!BR4) | BX4: =IF(ISBLANK(Lanes!BS4),"",Lanes!BS4) | BY4: =IF(ISBLANK(Lanes!BT4),"",Lanes!BT4) | BZ4: =IF(ISBLANK(Lanes!BU4),"",Lanes!BU4) | CA4: =IF(ISBLANK(Lanes!BV4),"",ROUND(Lanes!BV4,1)) | CB4: =IF(ISBLANK(Lanes!BW4),"",ROUND(Lanes!BW4,2)) | CC4: =IF(ISBLANK(Lanes!BX4),"",ROUND(Lanes!BX4,1)) | CD4: =IF(ISBLANK(Lanes!BY4),"",ROUND(Lanes!BY4,2)) | CE4: =IF(ISBLANK(Lanes!BZ4),"",ROUND(Lanes!BZ4,0)) | CF4: =IF(ISBLANK(Lanes!CA4),"",ROUND(Lanes!CA4,0)) | CG4: =IF(ISBLANK(Lanes!CB4),"",ROUND(Lanes!CB4,0)) | CH4: =IF(ISBLANK(Lanes!CC4),"",ROUND(Lanes!CC4,2)) | CI4: =IF(ISBLANK(Lanes!CD4),"",ROUND(Lanes!CD4,2)) | CJ4: =IF(ISBLANK(Lanes!CE4),"",ROUND(Lanes!CE4,2)) | CK4: =IF(ISBLANK(Lanes!CF4),"",ROUND(Lanes!CF4,0)) | CL4: =IF(ISBLANK(Lanes!CG4),"",ROUND(Lanes!CG4,0)) | CM4: =IF(ISBLANK(Lanes!CH4),"",ROUND(Lanes!CH4,0)) | CN4: =IF(ISBLANK(Lanes!CI4),"",ROUND(Lanes!CI4,2)) | CO4: =IF(ISBLANK(Lanes!CJ4),"",ROUND(Lanes!CJ4,2)) | CP4: =IF(ISBLANK(Lanes!CK4),"",ROUND(Lanes!CK4,2)) | CQ4: =IF(ISBLANK(Lanes!CL4),"","delete")
A5: 1409 | B5: 1094 | C5: 1 | D5: 104 | E5: 104 | F5: Existing | G5: Port to Port | H5: 40' RF | I5: Shanghai | J5: Shanghai | L5: China | M5: APAC | N5: Far East | O5: Bangkok | P5: Bangkok (Pat/Lat Krabang/Laem Chabang) | R5: Thailand | S5: APAC | T5: Far East | U5: Confectionary | V5: FOB | W5: Collect | X5: Receiving Unit | AA5: Yes | AB5: 70 | AC5: 2 | AD5: No | AE5: 0.25 | AF5: 0.25 | AG5: 0.25 | AH5: 0.25 | AI5: No | AJ5: 10 | AK5: 7 | AL5: 17 | AN5: 10 | AO5: 7 | AP5: 17 | AR5: 0.1 | AS5: USD | AT5: =IF(ISBLANK(Lanes!AO5),"",ROUND(Lanes!AO5,2)) | AU5: =IF(ISBLANK(Lanes!AP5),"",ROUND(Lanes!AP5,2)) | AV5: =IF(ISBLANK(Lanes!AQ5),"",ROUND(Lanes!AQ5,2)) | AW5: =IF(ISBLANK(Lanes!AP5),"",ROUND(Lanes!AR5,2)) | AX5: =IF(ISBLANK(Lanes!AS5),"",ROUND(Lanes!AS5,2)) | AY5: =IF(ISBLANK(Lanes!AT5),"",ROUND(Lanes!AT5,2)) | AZ5: =IF(ISBLANK(Lanes!AP5),"",ROUND(Lanes!AU5,2)) | BA5: =IF(ISBLANK(Lanes!AP5),"",ROUND(Lanes!AV5,2)) | BB5: =IF(ISBLANK(Lanes!AW5),"",ROUND(Lanes!AW5,2)) | BC5: =IF(ISBLANK(Lanes!AX5),"",ROUND(Lanes!AX5,2)) | BD5: =IF(ISBLANK(Lanes!AY5),"",ROUND(Lanes!AY5,2)) | BE5: =IF(ISBLANK(Lanes!AX5),"",ROUND(Lanes!AZ5,2)) | BF5: =IF(ISBLANK(Lanes!BA5),"",ROUND(Lanes!BA5,2)) | BG5: =IF(ISBLANK(Lanes!BB5),"",ROUND(Lanes!BB5,2)) | BH5: =IF(ISBLANK(Lanes!AX5),"",ROUND(Lanes!BC5,2)) | BI5: =IF(ISBLANK(Lanes!AX5),"",ROUND(Lanes!BD5,2)) | BJ5: =IF(ISBLANK(Lanes!BE5),"",Lanes!BE5) | BK5: =IF(ISBLANK(Lanes!BF5),"",Lanes!BF5) | BL5: =IF(ISBLANK(Lanes!BG5),"",Lanes!BG5) | BM5: =IF(ISBLANK(Lanes!BH5),"",Lanes!BH5) | BN5: =IF(ISBLANK(Lanes!BI5),"",Lanes!BI5) | BO5: =IF(ISBLANK(Lanes!BJ5),"",Lanes!BJ5) | BP5: =IF(ISBLANK(Lanes!BK5),"",Lanes!BK5) | BQ5: =IF(ISBLANK(Lanes!BL5),"",Lanes!BL5) | BR5: =IF(ISBLANK(Lanes!BM5),"",ROUND(Lanes!BM5,0)) | BS5: =IF(ISBLANK(Lanes!BN5),"",ROUND(Lanes!BN5,0)) | BT5: =IF(ISBLANK(Lanes!BO5),"",ROUND(Lanes!BO5,0)) | BU5: =IF(ISBLANK(Lanes!BN5),"",ROUND(Lanes!BP5,0)) | BV5: =IF(ISBLANK(Lanes!BQ5),"",ROUND(Lanes!BQ5,1)) | BW5: =IF(ISBLANK(Lanes!BR5),"",Lanes!BR5) | BX5: =IF(ISBLANK(Lanes!BS5),"",Lanes!BS5) | BY5: =IF(ISBLANK(Lanes!BT5),"",Lanes!BT5) | BZ5: =IF(ISBLANK(Lanes!BU5),"",Lanes!BU5) | CA5: =IF(ISBLANK(Lanes!BV5),"",ROUND(Lanes!BV5,1)) | CB5: =IF(ISBLANK(Lanes!BW5),"",ROUND(Lanes!BW5,2)) | CC5: =IF(ISBLANK(Lanes!BX5),"",ROUND(Lanes!BX5,1)) | CD5: =IF(ISBLANK(Lanes!BY5),"",ROUND(Lanes!BY5,2)) | CE5: =IF(ISBLANK(Lanes!BZ5),"",ROUND(Lanes!BZ5,0)) | CF5: =IF(ISBLANK(Lanes!CA5),"",ROUND(Lanes!CA5,0)) | CG5: =IF(ISBLANK(Lanes!CB5),"",ROUND(Lanes!CB5,0)) | CH5: =IF(ISBLANK(Lanes!CC5),"",ROUND(Lanes!CC5,2)) | CI5: =IF(ISBLANK(Lanes!CD5),"",ROUND(Lanes!CD5,2)) | CJ5: =IF(ISBLANK(Lanes!CE5),"",ROUND(Lanes!CE5,2)) | CK5: =IF(ISBLANK(Lanes!CF5),"",ROUND(Lanes!CF5,0)) | CL5: =IF(ISBLANK(Lanes!CG5),"",ROUND(Lanes!CG5,0)) | CM5: =IF(ISBLANK(Lanes!CH5),"",ROUND(Lanes!CH5,0)) | CN5: =IF(ISBLANK(Lanes!CI5),"",ROUND(Lanes!CI5,2)) | CO5: =IF(ISBLANK(Lanes!CJ5),"",ROUND(Lanes!CJ5,2)) | CP5: =IF(ISBLANK(Lanes!CK5),"",ROUND(Lanes!CK5,2)) | CQ5: =IF(ISBLANK(Lanes!CL5),"","delete")
A6: 1410 | B6: 1095 | C6: 1 | D6: 105 | E6: 105 | F6: Existing | G6: Port to Port | H6: 20' RF | I6: Shanghai | J6: Shanghai | L6: China | M6: APAC | N6: Far East | O6: Ho Chi Minh | P6: Cat Lai | R6: Vietnam | S6: APAC | T6: Far East | U6: Confectionary | V6: FOB | W6: Collect | X6: Receiving Unit | AA6: Yes | AB6: 5 | AC6: 1 | AD6: No | AE6: 0.25 | AF6: 0.25 | AG6: 0.25 | AH6: 0.25 | AI6: No | AJ6: 10 | AK6: 7 | AL6: 17 | AN6: 10 | AO6: 7 | AP6: 17 | AR6: 0.1 | AS6: USD | AT6: =IF(ISBLANK(Lanes!AO6),"",ROUND(Lanes!AO6,2)) | AU6: =IF(ISBLANK(Lanes!AP6),"",ROUND(Lanes!AP6,2)) | AV6: =IF(ISBLANK(Lanes!AQ6),"",ROUND(Lanes!AQ6,2)) | AW6: =IF(ISBLANK(Lanes!AP6),"",ROUND(Lanes!AR6,2)) | AX6: =IF(ISBLANK(Lanes!AS6),"",ROUND(Lanes!AS6,2)) | AY6: =IF(ISBLANK(Lanes!AT6),"",ROUND(Lanes!AT6,2)) | AZ6: =IF(ISBLANK(Lanes!AP6),"",ROUND(Lanes!AU6,2)) | BA6: =IF(ISBLANK(Lanes!AP6),"",ROUND(Lanes!AV6,2)) | BB6: =IF(ISBLANK(Lanes!AW6),"",ROUND(Lanes!AW6,2)) | BC6: =IF(ISBLANK(Lanes!AX6),"",ROUND(Lanes!AX6,2)) | BD6: =IF(ISBLANK(Lanes!AY6),"",ROUND(Lanes!AY6,2)) | BE6: =IF(ISBLANK(Lanes!AX6),"",ROUND(Lanes!AZ6,2)) | BF6: =IF(ISBLANK(Lanes!BA6),"",ROUND(Lanes!BA6,2)) | BG6: =IF(ISBLANK(Lanes!BB6),"",ROUND(Lanes!BB6,2)) | BH6: =IF(ISBLANK(Lanes!AX6),"",ROUND(Lanes!BC6,2)) | BI6: =IF(ISBLANK(Lanes!AX6),"",ROUND(Lanes!BD6,2)) | BJ6: =IF(ISBLANK(Lanes!BE6),"",Lanes!BE6) | BK6: =IF(ISBLANK(Lanes!BF6),"",Lanes!BF6) | BL6: =IF(ISBLANK(Lanes!BG6),"",Lanes!BG6) | BM6: =IF(ISBLANK(Lanes!BH6),"",Lanes!BH6) | BN6: =IF(ISBLANK(Lanes!BI6),"",Lanes!BI6) | BO6: =IF(ISBLANK(Lanes!BJ6),"",Lanes!BJ6) | BP6: =IF(ISBLANK(Lanes!BK6),"",Lanes!BK6) | BQ6: =IF(ISBLANK(Lanes!BL6),"",Lanes!BL6) | BR6: =IF(ISBLANK(Lanes!BM6),"",ROUND(Lanes!BM6,0)) | BS6: =IF(ISBLANK(Lanes!BN6),"",ROUND(Lanes!BN6,0)) | BT6: =IF(ISBLANK(Lanes!BO6),"",ROUND(Lanes!BO6,0)) | BU6: =IF(ISBLANK(Lanes!BN6),"",ROUND(Lanes!BP6,0)) | BV6: =IF(ISBLANK(Lanes!BQ6),"",ROUND(Lanes!BQ6,1)) | BW6: =IF(ISBLANK(Lanes!BR6),"",Lanes!BR6) | BX6: =IF(ISBLANK(Lanes!BS6),"",Lanes!BS6) | BY6: =IF(ISBLANK(Lanes!BT6),"",Lanes!BT6) | BZ6: =IF(ISBLANK(Lanes!BU6),"",Lanes!BU6) | CA6: =IF(ISBLANK(Lanes!BV6),"",ROUND(Lanes!BV6,1)) | CB6: =IF(ISBLANK(Lanes!BW6),"",ROUND(Lanes!BW6,2)) | CC6: =IF(ISBLANK(Lanes!BX6),"",ROUND(Lanes!BX6,1)) | CD6: =IF(ISBLANK(Lanes!BY6),"",ROUND(Lanes!BY6,2)) | CE6: =IF(ISBLANK(Lanes!BZ6),"",ROUND(Lanes!BZ6,0)) | CF6: =IF(ISBLANK(Lanes!CA6),"",ROUND(Lanes!CA6,0)) | CG6: =IF(ISBLANK(Lanes!CB6),"",ROUND(Lanes!CB6,0)) | CH6: =IF(ISBLANK(Lanes!CC6),"",ROUND(Lanes!CC6,2)) | CI6: =IF(ISBLANK(Lanes!CD6),"",ROUND(Lanes!CD6,2)) | CJ6: =IF(ISBLANK(Lanes!CE6),"",ROUND(Lanes!CE6,2)) | CK6: =IF(ISBLANK(Lanes!CF6),"",ROUND(Lanes!CF6,0)) | CL6: =IF(ISBLANK(Lanes!CG6),"",ROUND(Lanes!CG6,0)) | CM6: =IF(ISBLANK(Lanes!CH6),"",ROUND(Lanes!CH6,0)) | CN6: =IF(ISBLANK(Lanes!CI6),"",ROUND(Lanes!CI6,2)) | CO6: =IF(ISBLANK(Lanes!CJ6),"",ROUND(Lanes!CJ6,2)) | CP6: =IF(ISBLANK(Lanes!CK6),"",ROUND(Lanes!CK6,2)) | CQ6: =IF(ISBLANK(Lanes!CL6),"","delete")
A7: 1411 | B7: 1096 | C7: 1 | D7: 106 | E7: 106 | F7: Existing | G7: Port to Port | H7: 40' RF | I7: Shanghai | J7: Shanghai | L7: China | M7: APAC | N7: Far East | O7: Ho Chi Minh | P7: Cat Lai | R7: Vietnam | S7: APAC | T7: Far East | U7: Confectionary | V7: FOB | W7: Collect | X7: Receiving Unit | AA7: Yes | AB7: 45 | AC7: 1 | AD7: No | AE7: 0.25 | AF7: 0.25 | AG7: 0.25 | AH7: 0.25 | AI7: No | AJ7: 10 | AK7: 7 | AL7: 17 | AN7: 10 | AO7: 7 | AP7: 17 | AR7: 0.1 | AS7: USD | AT7: =IF(ISBLANK(Lanes!AO7),"",ROUND(Lanes!AO7,2)) | AU7: =IF(ISBLANK(Lanes!AP7),"",ROUND(Lanes!AP7,2)) | AV7: =IF(ISBLANK(Lanes!AQ7),"",ROUND(Lanes!AQ7,2)) | AW7: =IF(ISBLANK(Lanes!AP7),"",ROUND(Lanes!AR7,2)) | AX7: =IF(ISBLANK(Lanes!AS7),"",ROUND(Lanes!AS7,2)) | AY7: =IF(ISBLANK(Lanes!AT7),"",ROUND(Lanes!AT7,2)) | AZ7: =IF(ISBLANK(Lanes!AP7),"",ROUND(Lanes!AU7,2)) | BA7: =IF(ISBLANK(Lanes!AP7),"",ROUND(Lanes!AV7,2)) | BB7: =IF(ISBLANK(Lanes!AW7),"",ROUND(Lanes!AW7,2)) | BC7: =IF(ISBLANK(Lanes!AX7),"",ROUND(Lanes!AX7,2)) | BD7: =IF(ISBLANK(Lanes!AY7),"",ROUND(Lanes!AY7,2)) | BE7: =IF(ISBLANK(Lanes!AX7),"",ROUND(Lanes!AZ7,2)) | BF7: =IF(ISBLANK(Lanes!BA7),"",ROUND(Lanes!BA7,2)) | BG7: =IF(ISBLANK(Lanes!BB7),"",ROUND(Lanes!BB7,2)) | BH7: =IF(ISBLANK(Lanes!AX7),"",ROUND(Lanes!BC7,2)) | BI7: =IF(ISBLANK(Lanes!AX7),"",ROUND(Lanes!BD7,2)) | BJ7: =IF(ISBLANK(Lanes!BE7),"",Lanes!BE7) | BK7: =IF(ISBLANK(Lanes!BF7),"",Lanes!BF7) | BL7: =IF(ISBLANK(Lanes!BG7),"",Lanes!BG7) | BM7: =IF(ISBLANK(Lanes!BH7),"",Lanes!BH7) | BN7: =IF(ISBLANK(Lanes!BI7),"",Lanes!BI7) | BO7: =IF(ISBLANK(Lanes!BJ7),"",Lanes!BJ7) | BP7: =IF(ISBLANK(Lanes!BK7),"",Lanes!BK7) | BQ7: =IF(ISBLANK(Lanes!BL7),"",Lanes!BL7) | BR7: =IF(ISBLANK(Lanes!BM7),"",ROUND(Lanes!BM7,0)) | BS7: =IF(ISBLANK(Lanes!BN7),"",ROUND(Lanes!BN7,0)) | BT7: =IF(ISBLANK(Lanes!BO7),"",ROUND(Lanes!BO7,0)) | BU7: =IF(ISBLANK(Lanes!BN7),"",ROUND(Lanes!BP7,0)) | BV7: =IF(ISBLANK(Lanes!BQ7),"",ROUND(Lanes!BQ7,1)) | BW7: =IF(ISBLANK(Lanes!BR7),"",Lanes!BR7) | BX7: =IF(ISBLANK(Lanes!BS7),"",Lanes!BS7) | BY7: =IF(ISBLANK(Lanes!BT7),"",Lanes!BT7) | BZ7: =IF(ISBLANK(Lanes!BU7),"",Lanes!BU7) | CA7: =IF(ISBLANK(Lanes!BV7),"",ROUND(Lanes!BV7,1)) | CB7: =IF(ISBLANK(Lanes!BW7),"",ROUND(Lanes!BW7,2)) | CC7: =IF(ISBLANK(Lanes!BX7),"",ROUND(Lanes!BX7,1)) | CD7: =IF(ISBLANK(Lanes!BY7),"",ROUND(Lanes!BY7,2)) | CE7: =IF(ISBLANK(Lanes!BZ7),"",ROUND(Lanes!BZ7,0)) | CF7: =IF(ISBLANK(Lanes!CA7),"",ROUND(Lanes!CA7,0)) | CG7: =IF(ISBLANK(Lanes!CB7),"",ROUND(Lanes!CB7,0)) | CH7: =IF(ISBLANK(Lanes!CC7),"",ROUND(Lanes!CC7,2)) | CI7: =IF(ISBLANK(Lanes!CD7),"",ROUND(Lanes!CD7,2)) | CJ7: =IF(ISBLANK(Lanes!CE7),"",ROUND(Lanes!CE7,2)) | CK7: =IF(ISBLANK(Lanes!CF7),"",ROUND(Lanes!CF7,0)) | CL7: =IF(ISBLANK(Lanes!CG7),"",ROUND(Lanes!CG7,0)) | CM7: =IF(ISBLANK(Lanes!CH7),"",ROUND(Lanes!CH7,0)) | CN7: =IF(ISBLANK(Lanes!CI7),"",ROUND(Lanes!CI7,2)) | CO7: =IF(ISBLANK(Lanes!CJ7),"",ROUND(Lanes!CJ7,2)) | CP7: =IF(ISBLANK(Lanes!CK7),"",ROUND(Lanes!CK7,2)) | CQ7: =IF(ISBLANK(Lanes!CL7),"","delete")
A8: 1412 | B8: 1097 | C8: 1 | D8: 107 | E8: 107 | F8: Existing | G8: Port to Port | H8: 20' RF | I8: Shanghai | J8: Shanghai | L8: China | M8: APAC | N8: Far East | O8: Hong Kong | P8: Hong Kong | R8: Hong Kong | S8: APAC | T8: Far East | U8: Confectionary | V8: FOB | W8: Collect | X8: Receiving Unit | AA8: Yes | AB8: 12 | AC8: 1 | AD8: No | AE8: 0.25 | AF8: 0.25 | AG8: 0.25 | AH8: 0.25 | AI8: No | AJ8: 10 | AK8: 7 | AL8: 17 | AM8: 7 | AN8: 10 | AO8: 7 | AP8: 17 | AR8: 0.1 | AS8: USD | AT8: =IF(ISBLANK(Lanes!AO8),"",ROUND(Lanes!AO8,2)) | AU8: =IF(ISBLANK(Lanes!AP8),"",ROUND(Lanes!AP8,2)) | AV8: =IF(ISBLANK(Lanes!AQ8),"",ROUND(Lanes!AQ8,2)) | AW8: =IF(ISBLANK(Lanes!AP8),"",ROUND(Lanes!AR8,2)) | AX8: =IF(ISBLANK(Lanes!AS8),"",ROUND(Lanes!AS8,2)) | AY8: =IF(ISBLANK(Lanes!AT8),"",ROUND(Lanes!AT8,2)) | AZ8: =IF(ISBLANK(Lanes!AP8),"",ROUND(Lanes!AU8,2)) | BA8: =IF(ISBLANK(Lanes!AP8),"",ROUND(Lanes!AV8,2)) | BB8: =IF(ISBLANK(Lanes!AW8),"",ROUND(Lanes!AW8,2)) | BC8: =IF(ISBLANK(Lanes!AX8),"",ROUND(Lanes!AX8,2)) | BD8: =IF(ISBLANK(Lanes!AY8),"",ROUND(Lanes!AY8,2)) | BE8: =IF(ISBLANK(Lanes!AX8),"",ROUND(Lanes!AZ8,2)) | BF8: =IF(ISBLANK(Lanes!BA8),"",ROUND(Lanes!BA8,2)) | BG8: =IF(ISBLANK(Lanes!BB8),"",ROUND(Lanes!BB8,2)) | BH8: =IF(ISBLANK(Lanes!AX8),"",ROUND(Lanes!BC8,2)) | BI8: =IF(ISBLANK(Lanes!AX8),"",ROUND(Lanes!BD8,2)) | BJ8: =IF(ISBLANK(Lanes!BE8),"",Lanes!BE8) | BK8: =IF(ISBLANK(Lanes!BF8),"",Lanes!BF8) | BL8: =IF(ISBLANK(Lanes!BG8),"",Lanes!BG8) | BM8: =IF(ISBLANK(Lanes!BH8),"",Lanes!BH8) | BN8: =IF(ISBLANK(Lanes!BI8),"",Lanes!BI8) | BO8: =IF(ISBLANK(Lanes!BJ8),"",Lanes!BJ8) | BP8: =IF(ISBLANK(Lanes!BK8),"",Lanes!BK8) | BQ8: =IF(ISBLANK(Lanes!BL8),"",Lanes!BL8) | BR8: =IF(ISBLANK(Lanes!BM8),"",ROUND(Lanes!BM8,0)) | BS8: =IF(ISBLANK(Lanes!BN8),"",ROUND(Lanes!BN8,0)) | BT8: =IF(ISBLANK(Lanes!BO8),"",ROUND(Lanes!BO8,0)) | BU8: =IF(ISBLANK(Lanes!BN8),"",ROUND(Lanes!BP8,0)) | BV8: =IF(ISBLANK(Lanes!BQ8),"",ROUND(Lanes!BQ8,1)) | BW8: =IF(ISBLANK(Lanes!BR8),"",Lanes!BR8) | BX8: =IF(ISBLANK(Lanes!BS8),"",Lanes!BS8) | BY8: =IF(ISBLANK(Lanes!BT8),"",Lanes!BT8) | BZ8: =IF(ISBLANK(Lanes!BU8),"",Lanes!BU8) | CA8: =IF(ISBLANK(Lanes!BV8),"",ROUND(Lanes!BV8,1)) | CB8: =IF(ISBLANK(Lanes!BW8),"",ROUND(Lanes!BW8,2)) | CC8: =IF(ISBLANK(Lanes!BX8),"",ROUND(Lanes!BX8,1)) | CD8: =IF(ISBLANK(Lanes!BY8),"",ROUND(Lanes!BY8,2)) | CE8: =IF(ISBLANK(Lanes!BZ8),"",ROUND(Lanes!BZ8,0)) | CF8: =IF(ISBLANK(Lanes!CA8),"",ROUND(Lanes!CA8,0)) | CG8: =IF(ISBLANK(Lanes!CB8),"",ROUND(Lanes!CB8,0)) | CH8: =IF(ISBLANK(Lanes!CC8),"",ROUND(Lanes!CC8,2)) | CI8: =IF(ISBLANK(Lanes!CD8),"",ROUND(Lanes!CD8,2)) | CJ8: =IF(ISBLANK(Lanes!CE8),"",ROUND(Lanes!CE8,2)) | CK8: =IF(ISBLANK(Lanes!CF8),"",ROUND(Lanes!CF8,0)) | CL8: =IF(ISBLANK(Lanes!CG8),"",ROUND(Lanes!CG8,0)) | CM8: =IF(ISBLANK(Lanes!CH8),"",ROUND(Lanes!CH8,0)) | CN8: =IF(ISBLANK(Lanes!CI8),"",ROUND(Lanes!CI8,2)) | CO8: =IF(ISBLANK(Lanes!CJ8),"",ROUND(Lanes!CJ8,2)) | CP8: =IF(ISBLANK(Lanes!CK8),"",ROUND(Lanes!CK8,2)) | CQ8: =IF(ISBLANK(Lanes!CL8),"","delete")
A9: 1413 | B9: 1098 | C9: 1 | D9: 108 | E9: 108 | F9: Existing | G9: Port to Port | H9: 40' RF | I9: Shanghai | J9: Shanghai | L9: China | M9: APAC | N9: Far East | O9: Hong Kong | P9: Hong Kong | R9: Hong Kong | S9: APAC | T9: Far East | U9: Confectionary | V9: FOB | W9: Collect | X9: Receiving Unit | AA9: Yes | AB9: 38 | AC9: 1 | AD9: No | AE9: 0.25 | AF9: 0.25 | AG9: 0.25 | AH9: 0.25 | AI9: No | AJ9: 10 | AK9: 7 | AL9: 17 | AN9: 10 | AO9: 7 | AP9: 17 | AR9: 0.1 | AS9: USD | AT9: =IF(ISBLANK(Lanes!AO9),"",ROUND(Lanes!AO9,2)) | AU9: =IF(ISBLANK(Lanes!AP9),"",ROUND(Lanes!AP9,2)) | AV9: =IF(ISBLANK(Lanes!AQ9),"",ROUND(Lanes!AQ9,2)) | AW9: =IF(ISBLANK(Lanes!AP9),"",ROUND(Lanes!AR9,2)) | AX9: =IF(ISBLANK(Lanes!AS9),"",ROUND(Lanes!AS9,2)) | AY9: =IF(ISBLANK(Lanes!AT9),"",ROUND(Lanes!AT9,2)) | AZ9: =IF(ISBLANK(Lanes!AP9),"",ROUND(Lanes!AU9,2)) | BA9: =IF(ISBLANK(Lanes!AP9),"",ROUND(Lanes!AV9,2)) | BB9: =IF(ISBLANK(Lanes!AW9),"",ROUND(Lanes!AW9,2)) | BC9: =IF(ISBLANK(Lanes!AX9),"",ROUND(Lanes!AX9,2)) | BD9: =IF(ISBLANK(Lanes!AY9),"",ROUND(Lanes!AY9,2)) | BE9: =IF(ISBLANK(Lanes!AX9),"",ROUND(Lanes!AZ9,2)) | BF9: =IF(ISBLANK(Lanes!BA9),"",ROUND(Lanes!BA9,2)) | BG9: =IF(ISBLANK(Lanes!BB9),"",ROUND(Lanes!BB9,2)) | BH9: =IF(ISBLANK(Lanes!AX9),"",ROUND(Lanes!BC9,2)) | BI9: =IF(ISBLANK(Lanes!AX9),"",ROUND(Lanes!BD9,2)) | BJ9: =IF(ISBLANK(Lanes!BE9),"",Lanes!BE9) | BK9: =IF(ISBLANK(Lanes!BF9),"",Lanes!BF9) | BL9: =IF(ISBLANK(Lanes!BG9),"",Lanes!BG9) | BM9: =IF(ISBLANK(Lanes!BH9),"",Lanes!BH9) | BN9: =IF(ISBLANK(Lanes!BI9),"",Lanes!BI9) | BO9: =IF(ISBLANK(Lanes!BJ9),"",Lanes!BJ9) | BP9: =IF(ISBLANK(Lanes!BK9),"",Lanes!BK9) | BQ9: =IF(ISBLANK(Lanes!BL9),"",Lanes!BL9) | BR9: =IF(ISBLANK(Lanes!BM9),"",ROUND(Lanes!BM9,0)) | BS9: =IF(ISBLANK(Lanes!BN9),"",ROUND(Lanes!BN9,0)) | BT9: =IF(ISBLANK(Lanes!BO9),"",ROUND(Lanes!BO9,0)) | BU9: =IF(ISBLANK(Lanes!BN9),"",ROUND(Lanes!BP9,0)) | BV9: =IF(ISBLANK(Lanes!BQ9),"",ROUND(Lanes!BQ9,1)) | BW9: =IF(ISBLANK(Lanes!BR9),"",Lanes!BR9) | BX9: =IF(ISBLANK(Lanes!BS9),"",Lanes!BS9) | BY9: =IF(ISBLANK(Lanes!BT9),"",Lanes!BT9) | BZ9: =IF(ISBLANK(Lanes!BU9),"",Lanes!BU9) | CA9: =IF(ISBLANK(Lanes!BV9),"",ROUND(Lanes!BV9,1)) | CB9: =IF(ISBLANK(Lanes!BW9),"",ROUND(Lanes!BW9,2)) | CC9: =IF(ISBLANK(Lanes!BX9),"",ROUND(Lanes!BX9,1)) | CD9: =IF(ISBLANK(Lanes!BY9),"",ROUND(Lanes!BY9,2)) | CE9: =IF(ISBLANK(Lanes!BZ9),"",ROUND(Lanes!BZ9,0)) | CF9: =IF(ISBLANK(Lanes!CA9),"",ROUND(Lanes!CA9,0)) | CG9: =IF(ISBLANK(Lanes!CB9),"",ROUND(Lanes!CB9,0)) | CH9: =IF(ISBLANK(Lanes!CC9),"",ROUND(Lanes!CC9,2)) | CI9: =IF(ISBLANK(Lanes!CD9),"",ROUND(Lanes!CD9,2)) | CJ9: =IF(ISBLANK(Lanes!CE9),"",ROUND(Lanes!CE9,2)) | CK9: =IF(ISBLANK(Lanes!CF9),"",ROUND(Lanes!CF9,0)) | CL9: =IF(ISBLANK(Lanes!CG9),"",ROUND(Lanes!CG9,0)) | CM9: =IF(ISBLANK(Lanes!CH9),"",ROUND(Lanes!CH9,0)) | CN9: =IF(ISBLANK(Lanes!CI9),"",ROUND(Lanes!CI9,2)) | CO9: =IF(ISBLANK(Lanes!CJ9),"",ROUND(Lanes!CJ9,2)) | CP9: =IF(ISBLANK(Lanes!CK9),"",ROUND(Lanes!CK9,2)) | CQ9: =IF(ISBLANK(Lanes!CL9),"","delete")
A10: 1414 | B10: 1099 | C10: 1 | D10: 109 | E10: 109 | F10: Existing | G10: Port to Port | H10: 20' RF | I10: Shanghai | J10: Shanghai | L10: China | M10: APAC | N10: Far East | O10: Manila | P10: Manila | R10: Philippines | S10: APAC | T10: Far East | U10: Confectionary | V10: FOB | W10: Collect | X10: Receiving Unit | AA10: Yes | AB10: 10 | AC10: 1 | AD10: No | AE10: 0.25 | AF10: 0.25 | AG10: 0.25 | AH10: 0.25 | AI10: No | AJ10: 10 | AK10: 7 | AL10: 17 | AN10: 10 | AO10: 7 | AP10: 17 | AR10: 0.1 | AS10: USD | AT10: =IF(ISBLANK(Lanes!AO10),"",ROUND(Lanes!AO10,2)) | AU10: =IF(ISBLANK(Lanes!AP10),"",ROUND(Lanes!AP10,2)) | AV10: =IF(ISBLANK(Lanes!AQ10),"",ROUND(Lanes!AQ10,2)) | AW10: =IF(ISBLANK(Lanes!AP10),"",ROUND(Lanes!AR10,2)) | AX10: =IF(ISBLANK(Lanes!AS10),"",ROUND(Lanes!AS10,2)) | AY10: =IF(ISBLANK(Lanes!AT10),"",ROUND(Lanes!AT10,2)) | AZ10: =IF(ISBLANK(Lanes!AP10),"",ROUND(Lanes!AU10,2)) | BA10: =IF(ISBLANK(Lanes!AP10),"",ROUND(Lanes!AV10,2)) | BB10: =IF(ISBLANK(Lanes!AW10),"",ROUND(Lanes!AW10,2)) | BC10: =IF(ISBLANK(Lanes!AX10),"",ROUND(Lanes!AX10,2)) | BD10: =IF(ISBLANK(Lanes!AY10),"",ROUND(Lanes!AY10,2)) | BE10: =IF(ISBLANK(Lanes!AX10),"",ROUND(Lanes!AZ10,2)) | BF10: =IF(ISBLANK(Lanes!BA10),"",ROUND(Lanes!BA10,2)) | BG10: =IF(ISBLANK(Lanes!BB10),"",ROUND(Lanes!BB10,2)) | BH10: =IF(ISBLANK(Lanes!AX10),"",ROUND(Lanes!BC10,2)) | BI10: =IF(ISBLANK(Lanes!AX10),"",ROUND(Lanes!BD10,2)) | BJ10: =IF(ISBLANK(Lanes!BE10),"",Lanes!BE10) | BK10: =IF(ISBLANK(Lanes!BF10),"",Lanes!BF10) | BL10: =IF(ISBLANK(Lanes!BG10),"",Lanes!BG10) | BM10: =IF(ISBLANK(Lanes!BH10),"",Lanes!BH10) | BN10: =IF(ISBLANK(Lanes!BI10),"",Lanes!BI10) | BO10: =IF(ISBLANK(Lanes!BJ10),"",Lanes!BJ10) | BP10: =IF(ISBLANK(Lanes!BK10),"",Lanes!BK10) | BQ10: =IF(ISBLANK(Lanes!BL10),"",Lanes!BL10) | BR10: =IF(ISBLANK(Lanes!BM10),"",ROUND(Lanes!BM10,0)) | BS10: =IF(ISBLANK(Lanes!BN10),"",ROUND(Lanes!BN10,0)) | BT10: =IF(ISBLANK(Lanes!BO10),"",ROUND(Lanes!BO10,0)) | BU10: =IF(ISBLANK(Lanes!BN10),"",ROUND(Lanes!BP10,0)) | BV10: =IF(ISBLANK(Lanes!BQ10),"",ROUND(Lanes!BQ10,1)) | BW10: =IF(ISBLANK(Lanes!BR10),"",Lanes!BR10) | BX10: =IF(ISBLANK(Lanes!BS10),"",Lanes!BS10) | BY10: =IF(ISBLANK(Lanes!BT10),"",Lanes!BT10) | BZ10: =IF(ISBLANK(Lanes!BU10),"",Lanes!BU10) | CA10: =IF(ISBLANK(Lanes!BV10),"",ROUND(Lanes!BV10,1)) | CB10: =IF(ISBLANK(Lanes!BW10),"",ROUND(Lanes!BW10,2)) | CC10: =IF(ISBLANK(Lanes!BX10),"",ROUND(Lanes!BX10,1)) | CD10: =IF(ISBLANK(Lanes!BY10),"",ROUND(Lanes!BY10,2)) | CE10: =IF(ISBLANK(Lanes!BZ10),"",ROUND(Lanes!BZ10,0)) | CF10: =IF(ISBLANK(Lanes!CA10),"",ROUND(Lanes!CA10,0)) | CG10: =IF(ISBLANK(Lanes!CB10),"",ROUND(Lanes!CB10,0)) | CH10: =IF(ISBLANK(Lanes!CC10),"",ROUND(Lanes!CC10,2)) | CI10: =IF(ISBLANK(Lanes!CD10),"",ROUND(Lanes!CD10,2)) | CJ10: =IF(ISBLANK(Lanes!CE10),"",ROUND(Lanes!CE10,2)) | CK10: =IF(ISBLANK(Lanes!CF10),"",ROUND(Lanes!CF10,0)) | CL10: =IF(ISBLANK(Lanes!CG10),"",ROUND(Lanes!CG10,0)) | CM10: =IF(ISBLANK(Lanes!CH10),"",ROUND(Lanes!CH10,0)) | CN10: =IF(ISBLANK(Lanes!CI10),"",ROUND(Lanes!CI10,2)) | CO10: =IF(ISBLANK(Lanes!CJ10),"",ROUND(Lanes!CJ10,2)) | CP10: =IF(ISBLANK(Lanes!CK10),"",ROUND(Lanes!CK10,2)) | CQ10: =IF(ISBLANK(Lanes!CL10),"","delete")
A11: 1415 | B11: 1100 | C11: 1 | D11: 110 | E11: 110 | F11: Existing | G11: Port to Port | H11: 40' RF | I11: Shanghai | J11: Shanghai | L11: China | M11: APAC | N11: Far East | O11: Manila | P11: Manila | R11: Philippines | S11: APAC | T11: Far East | U11: Confectionary | V11: FOB | W11: Collect | X11: Receiving Unit | AA11: Yes | AB11: 186 | AC11: 4 | AD11: No | AE11: 0.25 | AF11: 0.25 | AG11: 0.25 | AH11: 0.25 | AI11: No | AJ11: 10 | AK11: 7 | AL11: 17 | AN11: 10 | AO11: 7 | AP11: 17 | AR11: 0.1 | AS11: USD | AT11: =IF(ISBLANK(Lanes!AO11),"",ROUND(Lanes!AO11,2)) | AU11: =IF(ISBLANK(Lanes!AP11),"",ROUND(Lanes!AP11,2)) | AV11: =IF(ISBLANK(Lanes!AQ11),"",ROUND(Lanes!AQ11,2)) | AW11: =IF(ISBLANK(Lanes!AP11),"",ROUND(Lanes!AR11,2)) | AX11: =IF(ISBLANK(Lanes!AS11),"",ROUND(Lanes!AS11,2)) | AY11: =IF(ISBLANK(Lanes!AT11),"",ROUND(Lanes!AT11,2)) | AZ11: =IF(ISBLANK(Lanes!AP11),"",ROUND(Lanes!AU11,2)) | BA11: =IF(ISBLANK(Lanes!AP11),"",ROUND(Lanes!AV11,2)) | BB11: =IF(ISBLANK(Lanes!AW11),"",ROUND(Lanes!AW11,2)) | BC11: =IF(ISBLANK(Lanes!AX11),"",ROUND(Lanes!AX11,2)) | BD11: =IF(ISBLANK(Lanes!AY11),"",ROUND(Lanes!AY11,2)) | BE11: =IF(ISBLANK(Lanes!AX11),"",ROUND(Lanes!AZ11,2)) | BF11: =IF(ISBLANK(Lanes!BA11),"",ROUND(Lanes!BA11,2)) | BG11: =IF(ISBLANK(Lanes!BB11),"",ROUND(Lanes!BB11,2)) | BH11: =IF(ISBLANK(Lanes!AX11),"",ROUND(Lanes!BC11,2)) | BI11: =IF(ISBLANK(Lanes!AX11),"",ROUND(Lanes!BD11,2)) | BJ11: =IF(ISBLANK(Lanes!BE11),"",Lanes!BE11) | BK11: =IF(ISBLANK(Lanes!BF11),"",Lanes!BF11) | BL11: =IF(ISBLANK(Lanes!BG11),"",Lanes!BG11) | BM11: =IF(ISBLANK(Lanes!BH11),"",Lanes!BH11) | BN11: =IF(ISBLANK(Lanes!BI11),"",Lanes!BI11) | BO11: =IF(ISBLANK(Lanes!BJ11),"",Lanes!BJ11) | BP11: =IF(ISBLANK(Lanes!BK11),"",Lanes!BK11) | BQ11: =IF(ISBLANK(Lanes!BL11),"",Lanes!BL11) | BR11: =IF(ISBLANK(Lanes!BM11),"",ROUND(Lanes!BM11,0)) | BS11: =IF(ISBLANK(Lanes!BN11),"",ROUND(Lanes!BN11,0)) | BT11: =IF(ISBLANK(Lanes!BO11),"",ROUND(Lanes!BO11,0)) | BU11: =IF(ISBLANK(Lanes!BN11),"",ROUND(Lanes!BP11,0)) | BV11: =IF(ISBLANK(Lanes!BQ11),"",ROUND(Lanes!BQ11,1)) | BW11: =IF(ISBLANK(Lanes!BR11),"",Lanes!BR11) | BX11: =IF(ISBLANK(Lanes!BS11),"",Lanes!BS11) | BY11: =IF(ISBLANK(Lanes!BT11),"",Lanes!BT11) | BZ11: =IF(ISBLANK(Lanes!BU11),"",Lanes!BU11) | CA11: =IF(ISBLANK(Lanes!BV11),"",ROUND(Lanes!BV11,1)) | CB11: =IF(ISBLANK(Lanes!BW11),"",ROUND(Lanes!BW11,2)) | CC11: =IF(ISBLANK(Lanes!BX11),"",ROUND(Lanes!BX11,1)) | CD11: =IF(ISBLANK(Lanes!BY11),"",ROUND(Lanes!BY11,2)) | CE11: =IF(ISBLANK(Lanes!BZ11),"",ROUND(Lanes!BZ11,0)) | CF11: =IF(ISBLANK(Lanes!CA11),"",ROUND(Lanes!CA11,0)) | CG11: =IF(ISBLANK(Lanes!CB11),"",ROUND(Lanes!CB11,0)) | CH11: =IF(ISBLANK(Lanes!CC11),"",ROUND(Lanes!CC11,2)) | CI11: =IF(ISBLANK(Lanes!CD11),"",ROUND(Lanes!CD11,2)) | CJ11: =IF(ISBLANK(Lanes!CE11),"",ROUND(Lanes!CE11,2)) | CK11: =IF(ISBLANK(Lanes!CF11),"",ROUND(Lanes!CF11,0)) | CL11: =IF(ISBLANK(Lanes!CG11),"",ROUND(Lanes!CG11,0)) | CM11: =IF(ISBLANK(Lanes!CH11),"",ROUND(Lanes!CH11,0)) | CN11: =IF(ISBLANK(Lanes!CI11),"",ROUND(Lanes!CI11,2)) | CO11: =IF(ISBLANK(Lanes!CJ11),"",ROUND(Lanes!CJ11,2)) | CP11: =IF(ISBLANK(Lanes!CK11),"",ROUND(Lanes!CK11,2)) | CQ11: =IF(ISBLANK(Lanes!CL11),"","delete")
A12: 1416 | B12: 1101 | C12: 1 | D12: 111 | E12: 111 | F12: Existing | G12: Port to Port | H12: 20' RF | I12: Shanghai | J12: Shanghai | L12: China | M12: APAC | N12: Far East | O12: Port Klang | P12: Port Klang | R12: Malaysia | S12: APAC | T12: Far East | U12: Confectionary | V12: FOB | W12: Collect | X12: Receiving Unit | AA12: Yes | AB12: 5 | AC12: 1 | AD12: No | AE12: 0.25 | AF12: 0.25 | AG12: 0.25 | AH12: 0.25 | AI12: No | AJ12: 10 | AK12: 7 | AL12: 17 | AN12: 10 | AO12: 7 | AP12: 17 | AR12: 0.1 | AS12: USD | AT12: =IF(ISBLANK(Lanes!AO12),"",ROUND(Lanes!AO12,2)) | AU12: =IF(ISBLANK(Lanes!AP12),"",ROUND(Lanes!AP12,2)) | AV12: =IF(ISBLANK(Lanes!AQ12),"",ROUND(Lanes!AQ12,2)) | AW12: =IF(ISBLANK(Lanes!AP12),"",ROUND(Lanes!AR12,2)) | AX12: =IF(ISBLANK(Lanes!AS12),"",ROUND(Lanes!AS12,2)) | AY12: =IF(ISBLANK(Lanes!AT12),"",ROUND(Lanes!AT12,2)) | AZ12: =IF(ISBLANK(Lanes!AP12),"",ROUND(Lanes!AU12,2)) | BA12: =IF(ISBLANK(Lanes!AP12),"",ROUND(Lanes!AV12,2)) | BB12: =IF(ISBLANK(Lanes!AW12),"",ROUND(Lanes!AW12,2)) | BC12: =IF(ISBLANK(Lanes!AX12),"",ROUND(Lanes!AX12,2)) | BD12: =IF(ISBLANK(Lanes!AY12),"",ROUND(Lanes!AY12,2)) | BE12: =IF(ISBLANK(Lanes!AX12),"",ROUND(Lanes!AZ12,2)) | BF12: =IF(ISBLANK(Lanes!BA12),"",ROUND(Lanes!BA12,2)) | BG12: =IF(ISBLANK(Lanes!BB12),"",ROUND(Lanes!BB12,2)) | BH12: =IF(ISBLANK(Lanes!AX12),"",ROUND(Lanes!BC12,2)) | BI12: =IF(ISBLANK(Lanes!AX12),"",ROUND(Lanes!BD12,2)) | BJ12: =IF(ISBLANK(Lanes!BE12),"",Lanes!BE12) | BK12: =IF(ISBLANK(Lanes!BF12),"",Lanes!BF12) | BL12: =IF(ISBLANK(Lanes!BG12),"",Lanes!BG12) | BM12: =IF(ISBLANK(Lanes!BH12),"",Lanes!BH12) | BN12: =IF(ISBLANK(Lanes!BI12),"",Lanes!BI12) | BO12: =IF(ISBLANK(Lanes!BJ12),"",Lanes!BJ12) | BP12: =IF(ISBLANK(Lanes!BK12),"",Lanes!BK12) | BQ12: =IF(ISBLANK(Lanes!BL12),"",Lanes!BL12) | BR12: =IF(ISBLANK(Lanes!BM12),"",ROUND(Lanes!BM12,0)) | BS12: =IF(ISBLANK(Lanes!BN12),"",ROUND(Lanes!BN12,0)) | BT12: =IF(ISBLANK(Lanes!BO12),"",ROUND(Lanes!BO12,0)) | BU12: =IF(ISBLANK(Lanes!BN12),"",ROUND(Lanes!BP12,0)) | BV12: =IF(ISBLANK(Lanes!BQ12),"",ROUND(Lanes!BQ12,1)) | BW12: =IF(ISBLANK(Lanes!BR12),"",Lanes!BR12) | BX12: =IF(ISBLANK(Lanes!BS12),"",Lanes!BS12) | BY12: =IF(ISBLANK(Lanes!BT12),"",Lanes!BT12) | BZ12: =IF(ISBLANK(Lanes!BU12),"",Lanes!BU12) | CA12: =IF(ISBLANK(Lanes!BV12),"",ROUND(Lanes!BV12,1)) | CB12: =IF(ISBLANK(Lanes!BW12),"",ROUND(Lanes!BW12,2)) | CC12: =IF(ISBLANK(Lanes!BX12),"",ROUND(Lanes!BX12,1)) | CD12: =IF(ISBLANK(Lanes!BY12),"",ROUND(Lanes!BY12,2)) | CE12: =IF(ISBLANK(Lanes!BZ12),"",ROUND(Lanes!BZ12,0)) | CF12: =IF(ISBLANK(Lanes!CA12),"",ROUND(Lanes!CA12,0)) | CG12: =IF(ISBLANK(Lanes!CB12),"",ROUND(Lanes!CB12,0)) | CH12: =IF(ISBLANK(Lanes!CC12),"",ROUND(Lanes!CC12,2)) | CI12: =IF(ISBLANK(Lanes!CD12),"",ROUND(Lanes!CD12,2)) | CJ12: =IF(ISBLANK(Lanes!CE12),"",ROUND(Lanes!CE12,2)) | CK12: =IF(ISBLANK(Lanes!CF12),"",ROUND(Lanes!CF12,0)) | CL12: =IF(ISBLANK(Lanes!CG12),"",ROUND(Lanes!CG12,0)) | CM12: =IF(ISBLANK(Lanes!CH12),"",ROUND(Lanes!CH12,0)) | CN12: =IF(ISBLANK(Lanes!CI12),"",ROUND(Lanes!CI12,2)) | CO12: =IF(ISBLANK(Lanes!CJ12),"",ROUND(Lanes!CJ12,2)) | CP12: =IF(ISBLANK(Lanes!CK12),"",ROUND(Lanes!CK12,2)) | CQ12: =IF(ISBLANK(Lanes!CL12),"","delete")
A13: 1417 | B13: 1102 | C13: 1 | D13: 112 | E13: 112 | F13: Existing | G13: Port to Port | H13: 40' RF | I13: Shanghai | J13: Shanghai | L13: China | M13: APAC | N13: Far East | O13: Port Klang | P13: Port Klang | R13: Malaysia | S13: APAC | T13: Far East | U13: Confectionary | V13: FOB | W13: Collect | X13: Receiving Unit | AA13: Yes | AB13: 100 | AC13: 2 | AD13: No | AE13: 0.25 | AF13: 0.25 | AG13: 0.25 | AH13: 0.25 | AI13: No | AJ13: 10 | AK13: 7 | AL13: 17 | AN13: 10 | AO13: 7 | AP13: 17 | AR13: 0.1 | AS13: USD | AT13: =IF(ISBLANK(Lanes!AO13),"",ROUND(Lanes!AO13,2)) | AU13: =IF(ISBLANK(Lanes!AP13),"",ROUND(Lanes!AP13,2)) | AV13: =IF(ISBLANK(Lanes!AQ13),"",ROUND(Lanes!AQ13,2)) | AW13: =IF(ISBLANK(Lanes!AP13),"",ROUND(Lanes!AR13,2)) | AX13: =IF(ISBLANK(Lanes!AS13),"",ROUND(Lanes!AS13,2)) | AY13: =IF(ISBLANK(Lanes!AT13),"",ROUND(Lanes!AT13,2)) | AZ13: =IF(ISBLANK(Lanes!AP13),"",ROUND(Lanes!AU13,2)) | BA13: =IF(ISBLANK(Lanes!AP13),"",ROUND(Lanes!AV13,2)) | BB13: =IF(ISBLANK(Lanes!AW13),"",ROUND(Lanes!AW13,2)) | BC13: =IF(ISBLANK(Lanes!AX13),"",ROUND(Lanes!AX13,2)) | BD13: =IF(ISBLANK(Lanes!AY13),"",ROUND(Lanes!AY13,2)) | BE13: =IF(ISBLANK(Lanes!AX13),"",ROUND(Lanes!AZ13,2)) | BF13: =IF(ISBLANK(Lanes!BA13),"",ROUND(Lanes!BA13,2)) | BG13: =IF(ISBLANK(Lanes!BB13),"",ROUND(Lanes!BB13,2)) | BH13: =IF(ISBLANK(Lanes!AX13),"",ROUND(Lanes!BC13,2)) | BI13: =IF(ISBLANK(Lanes!AX13),"",ROUND(Lanes!BD13,2)) | BJ13: =IF(ISBLANK(Lanes!BE13),"",Lanes!BE13) | BK13: =IF(ISBLANK(Lanes!BF13),"",Lanes!BF13) | BL13: =IF(ISBLANK(Lanes!BG13),"",Lanes!BG13) | BM13: =IF(ISBLANK(Lanes!BH13),"",Lanes!BH13) | BN13: =IF(ISBLANK(Lanes!BI13),"",Lanes!BI13) | BO13: =IF(ISBLANK(Lanes!BJ13),"",Lanes!BJ13) | BP13: =IF(ISBLANK(Lanes!BK13),"",Lanes!BK13) | BQ13: =IF(ISBLANK(Lanes!BL13),"",Lanes!BL13) | BR13: =IF(ISBLANK(Lanes!BM13),"",ROUND(Lanes!BM13,0)) | BS13: =IF(ISBLANK(Lanes!BN13),"",ROUND(Lanes!BN13,0)) | BT13: =IF(ISBLANK(Lanes!BO13),"",ROUND(Lanes!BO13,0)) | BU13: =IF(ISBLANK(Lanes!BN13),"",ROUND(Lanes!BP13,0)) | BV13: =IF(ISBLANK(Lanes!BQ13),"",ROUND(Lanes!BQ13,1)) | BW13: =IF(ISBLANK(Lanes!BR13),"",Lanes!BR13) | BX13: =IF(ISBLANK(Lanes!BS13),"",Lanes!BS13) | BY13: =IF(ISBLANK(Lanes!BT13),"",Lanes!BT13) | BZ13: =IF(ISBLANK(Lanes!BU13),"",Lanes!BU13) | CA13: =IF(ISBLANK(Lanes!BV13),"",ROUND(Lanes!BV13,1)) | CB13: =IF(ISBLANK(Lanes!BW13),"",ROUND(Lanes!BW13,2)) | CC13: =IF(ISBLANK(Lanes!BX13),"",ROUND(Lanes!BX13,1)) | CD13: =IF(ISBLANK(Lanes!BY13),"",ROUND(Lanes!BY13,2)) | CE13: =IF(ISBLANK(Lanes!BZ13),"",ROUND(Lanes!BZ13,0)) | CF13: =IF(ISBLANK(Lanes!CA13),"",ROUND(Lanes!CA13,0)) | CG13: =IF(ISBLANK(Lanes!CB13),"",ROUND(Lanes!CB13,0)) | CH13: =IF(ISBLANK(Lanes!CC13),"",ROUND(Lanes!CC13,2)) | CI13: =IF(ISBLANK(Lanes!CD13),"",ROUND(Lanes!CD13,2)) | CJ13: =IF(ISBLANK(Lanes!CE13),"",ROUND(Lanes!CE13,2)) | CK13: =IF(ISBLANK(Lanes!CF13),"",ROUND(Lanes!CF13,0)) | CL13: =IF(ISBLANK(Lanes!CG13),"",ROUND(Lanes!CG13,0)) | CM13: =IF(ISBLANK(Lanes!CH13),"",ROUND(Lanes!CH13,0)) | CN13: =IF(ISBLANK(Lanes!CI13),"",ROUND(Lanes!CI13,2)) | CO13: =IF(ISBLANK(Lanes!CJ13),"",ROUND(Lanes!CJ13,2)) | CP13: =IF(ISBLANK(Lanes!CK13),"",ROUND(Lanes!CK13,2)) | CQ13: =IF(ISBLANK(Lanes!CL13),"","delete")
A14: 1418 | B14: 1103 | C14: 1 | D14: 113 | E14: 113 | F14: Existing | G14: Port to Port | H14: 20' RF | I14: Shanghai | J14: Shanghai | L14: China | M14: APAC | N14: Far East | O14: Singapore | P14: Singapore | R14: Singapore | S14: APAC | T14: Far East | U14: Confectionary | V14: FOB | W14: Collect | X14: Receiving Unit | AA14: Yes | AB14: 5 | AC14: 1 | AD14: No | AE14: 0.25 | AF14: 0.25 | AG14: 0.25 | AH14: 0.25 | AI14: No | AJ14: 10 | AK14: 7 | AL14: 17 | AN14: 10 | AO14: 7 | AP14: 17 | AR14: 0.1 | AS14: USD | AT14: =IF(ISBLANK(Lanes!AO14),"",ROUND(Lanes!AO14,2)) | AU14: =IF(ISBLANK(Lanes!AP14),"",ROUND(Lanes!AP14,2)) | AV14: =IF(ISBLANK(Lanes!AQ14),"",ROUND(Lanes!AQ14,2)) | AW14: =IF(ISBLANK(Lanes!AP14),"",ROUND(Lanes!AR14,2)) | AX14: =IF(ISBLANK(Lanes!AS14),"",ROUND(Lanes!AS14,2)) | AY14: =IF(ISBLANK(Lanes!AT14),"",ROUND(Lanes!AT14,2)) | AZ14: =IF(ISBLANK(Lanes!AP14),"",ROUND(Lanes!AU14,2)) | BA14: =IF(ISBLANK(Lanes!AP14),"",ROUND(Lanes!AV14,2)) | BB14: =IF(ISBLANK(Lanes!AW14),"",ROUND(Lanes!AW14,2)) | BC14: =IF(ISBLANK(Lanes!AX14),"",ROUND(Lanes!AX14,2)) | BD14: =IF(ISBLANK(Lanes!AY14),"",ROUND(Lanes!AY14,2)) | BE14: =IF(ISBLANK(Lanes!AX14),"",ROUND(Lanes!AZ14,2)) | BF14: =IF(ISBLANK(Lanes!BA14),"",ROUND(Lanes!BA14,2)) | BG14: =IF(ISBLANK(Lanes!BB14),"",ROUND(Lanes!BB14,2)) | BH14: =IF(ISBLANK(Lanes!AX14),"",ROUND(Lanes!BC14,2)) | BI14: =IF(ISBLANK(Lanes!AX14),"",ROUND(Lanes!BD14,2)) | BJ14: =IF(ISBLANK(Lanes!BE14),"",Lanes!BE14) | BK14: =IF(ISBLANK(Lanes!BF14),"",Lanes!BF14) | BL14: =IF(ISBLANK(Lanes!BG14),"",Lanes!BG14) | BM14: =IF(ISBLANK(Lanes!BH14),"",Lanes!BH14) | BN14: =IF(ISBLANK(Lanes!BI14),"",Lanes!BI14) | BO14: =IF(ISBLANK(Lanes!BJ14),"",Lanes!BJ14) | BP14: =IF(ISBLANK(Lanes!BK14),"",Lanes!BK14) | BQ14: =IF(ISBLANK(Lanes!BL14),"",Lanes!BL14) | BR14: =IF(ISBLANK(Lanes!BM14),"",ROUND(Lanes!BM14,0)) | BS14: =IF(ISBLANK(Lanes!BN14),"",ROUND(Lanes!BN14,0)) | BT14: =IF(ISBLANK(Lanes!BO14),"",ROUND(Lanes!BO14,0)) | BU14: =IF(ISBLANK(Lanes!BN14),"",ROUND(Lanes!BP14,0)) | BV14: =IF(ISBLANK(Lanes!BQ14),"",ROUND(Lanes!BQ14,1)) | BW14: =IF(ISBLANK(Lanes!BR14),"",Lanes!BR14) | BX14: =IF(ISBLANK(Lanes!BS14),"",Lanes!BS14) | BY14: =IF(ISBLANK(Lanes!BT14),"",Lanes!BT14) | BZ14: =IF(ISBLANK(Lanes!BU14),"",Lanes!BU14) | CA14: =IF(ISBLANK(Lanes!BV14),"",ROUND(Lanes!BV14,1)) | CB14: =IF(ISBLANK(Lanes!BW14),"",ROUND(Lanes!BW14,2)) | CC14: =IF(ISBLANK(Lanes!BX14),"",ROUND(Lanes!BX14,1)) | CD14: =IF(ISBLANK(Lanes!BY14),"",ROUND(Lanes!BY14,2)) | CE14: =IF(ISBLANK(Lanes!BZ14),"",ROUND(Lanes!BZ14,0)) | CF14: =IF(ISBLANK(Lanes!CA14),"",ROUND(Lanes!CA14,0)) | CG14: =IF(ISBLANK(Lanes!CB14),"",ROUND(Lanes!CB14,0)) | CH14: =IF(ISBLANK(Lanes!CC14),"",ROUND(Lanes!CC14,2)) | CI14: =IF(ISBLANK(Lanes!CD14),"",ROUND(Lanes!CD14,2)) | CJ14: =IF(ISBLANK(Lanes!CE14),"",ROUND(Lanes!CE14,2)) | CK14: =IF(ISBLANK(Lanes!CF14),"",ROUND(Lanes!CF14,0)) | CL14: =IF(ISBLANK(Lanes!CG14),"",ROUND(Lanes!CG14,0)) | CM14: =IF(ISBLANK(Lanes!CH14),"",ROUND(Lanes!CH14,0)) | CN14: =IF(ISBLANK(Lanes!CI14),"",ROUND(Lanes!CI14,2)) | CO14: =IF(ISBLANK(Lanes!CJ14),"",ROUND(Lanes!CJ14,2)) | CP14: =IF(ISBLANK(Lanes!CK14),"",ROUND(Lanes!CK14,2)) | CQ14: =IF(ISBLANK(Lanes!CL14),"","delete")
A15: 1419 | B15: 1104 | C15: 1 | D15: 114 | E15: 114 | F15: Existing | G15: Port to Port | H15: 40' RF | I15: Shanghai | J15: Shanghai | L15: China | M15: APAC | N15: Far East | O15: Singapore | P15: Singapore | R15: Singapore | S15: APAC | T15: Far East | U15: Confectionary | V15: FOB | W15: Collect | X15: Receiving Unit | AA15: Yes | AB15: 45 | AC15: 1 | AD15: No | AE15: 0.25 | AF15: 0.25 | AG15: 0.25 | AH15: 0.25 | AI15: No | AJ15: 10 | AK15: 7 | AL15: 17 | AN15: 10 | AO15: 7 | AP15: 17 | AR15: 0.1 | AS15: USD | AT15: =IF(ISBLANK(Lanes!AO15),"",ROUND(Lanes!AO15,2)) | AU15: =IF(ISBLANK(Lanes!AP15),"",ROUND(Lanes!AP15,2)) | AV15: =IF(ISBLANK(Lanes!AQ15),"",ROUND(Lanes!AQ15,2)) | AW15: =IF(ISBLANK(Lanes!AP15),"",ROUND(Lanes!AR15,2)) | AX15: =IF(ISBLANK(Lanes!AS15),"",ROUND(Lanes!AS15,2)) | AY15: =IF(ISBLANK(Lanes!AT15),"",ROUND(Lanes!AT15,2)) | AZ15: =IF(ISBLANK(Lanes!AP15),"",ROUND(Lanes!AU15,2)) | BA15: =IF(ISBLANK(Lanes!AP15),"",ROUND(Lanes!AV15,2)) | BB15: =IF(ISBLANK(Lanes!AW15),"",ROUND(Lanes!AW15,2)) | BC15: =IF(ISBLANK(Lanes!AX15),"",ROUND(Lanes!AX15,2)) | BD15: =IF(ISBLANK(Lanes!AY15),"",ROUND(Lanes!AY15,2)) | BE15: =IF(ISBLANK(Lanes!AX15),"",ROUND(Lanes!AZ15,2)) | BF15: =IF(ISBLANK(Lanes!BA15),"",ROUND(Lanes!BA15,2)) | BG15: =IF(ISBLANK(Lanes!BB15),"",ROUND(Lanes!BB15,2)) | BH15: =IF(ISBLANK(Lanes!AX15),"",ROUND(Lanes!BC15,2)) | BI15: =IF(ISBLANK(Lanes!AX15),"",ROUND(Lanes!BD15,2)) | BJ15: =IF(ISBLANK(Lanes!BE15),"",Lanes!BE15) | BK15: =IF(ISBLANK(Lanes!BF15),"",Lanes!BF15) | BL15: =IF(ISBLANK(Lanes!BG15),"",Lanes!BG15) | BM15: =IF(ISBLANK(Lanes!BH15),"",Lanes!BH15) | BN15: =IF(ISBLANK(Lanes!BI15),"",Lanes!BI15) | BO15: =IF(ISBLANK(Lanes!BJ15),"",Lanes!BJ15) | BP15: =IF(ISBLANK(Lanes!BK15),"",Lanes!BK15) | BQ15: =IF(ISBLANK(Lanes!BL15),"",Lanes!BL15) | BR15: =IF(ISBLANK(Lanes!BM15),"",ROUND(Lanes!BM15,0)) | BS15: =IF(ISBLANK(Lanes!BN15),"",ROUND(Lanes!BN15,0)) | BT15: =IF(ISBLANK(Lanes!BO15),"",ROUND(Lanes!BO15,0)) | BU15: =IF(ISBLANK(Lanes!BN15),"",ROUND(Lanes!BP15,0)) | BV15: =IF(ISBLANK(Lanes!BQ15),"",ROUND(Lanes!BQ15,1)) | BW15: =IF(ISBLANK(Lanes!BR15),"",Lanes!BR15) | BX15: =IF(ISBLANK(Lanes!BS15),"",Lanes!BS15) | BY15: =IF(ISBLANK(Lanes!BT15),"",Lanes!BT15) | BZ15: =IF(ISBLANK(Lanes!BU15),"",Lanes!BU15) | CA15: =IF(ISBLANK(Lanes!BV15),"",ROUND(Lanes!BV15,1)) | CB15: =IF(ISBLANK(Lanes!BW15),"",ROUND(Lanes!BW15,2)) | CC15: =IF(ISBLANK(Lanes!BX15),"",ROUND(Lanes!BX15,1)) | CD15: =IF(ISBLANK(Lanes!BY15),"",ROUND(Lanes!BY15,2)) | CE15: =IF(ISBLANK(Lanes!BZ15),"",ROUND(Lanes!BZ15,0)) | CF15: =IF(ISBLANK(Lanes!CA15),"",ROUND(Lanes!CA15,0)) | CG15: =IF(ISBLANK(Lanes!CB15),"",ROUND(Lanes!CB15,0)) | CH15: =IF(ISBLANK(Lanes!CC15),"",ROUND(Lanes!CC15,2)) | CI15: =IF(ISBLANK(Lanes!CD15),"",ROUND(Lanes!CD15,2)) | CJ15: =IF(ISBLANK(Lanes!CE15),"",ROUND(Lanes!CE15,2)) | CK15: =IF(ISBLANK(Lanes!CF15),"",ROUND(Lanes!CF15,0)) | CL15: =IF(ISBLANK(Lanes!CG15),"",ROUND(Lanes!CG15,0)) | CM15: =IF(ISBLANK(Lanes!CH15),"",ROUND(Lanes!CH15,0)) | CN15: =IF(ISBLANK(Lanes!CI15),"",ROUND(Lanes!CI15,2)) | CO15: =IF(ISBLANK(Lanes!CJ15),"",ROUND(Lanes!CJ15,2)) | CP15: =IF(ISBLANK(Lanes!CK15),"",ROUND(Lanes!CK15,2)) | CQ15: =IF(ISBLANK(Lanes!CL15),"","delete")
A16: 1420 | B16: 1105 | C16: 1 | D16: 115 | E16: 115 | F16: Existing | G16: Port to Port | H16: 20' RF | I16: Shanghai | J16: Shanghai | L16: China | M16: APAC | N16: Far East | O16: Tokyo | P16: Tokyo | R16: Japan | S16: APAC | T16: Far East | U16: Confectionary | V16: FOB | W16: Collect | X16: Receiving Unit | AA16: Yes | AB16: 10 | AC16: 1 | AD16: No | AE16: 0.25 | AF16: 0.25 | AG16: 0.25 | AH16: 0.25 | AI16: No | AJ16: 10 | AK16: 7 | AL16: 17 | AN16: 9 | AO16: 9 | AP16: 0 | AR16: 0.1 | AS16: USD | AT16: =IF(ISBLANK(Lanes!AO16),"",ROUND(Lanes!AO16,2)) | AU16: =IF(ISBLANK(Lanes!AP16),"",ROUND(Lanes!AP16,2)) | AV16: =IF(ISBLANK(Lanes!AQ16),"",ROUND(Lanes!AQ16,2)) | AW16: =IF(ISBLANK(Lanes!AP16),"",ROUND(Lanes!AR16,2)) | AX16: =IF(ISBLANK(Lanes!AS16),"",ROUND(Lanes!AS16,2)) | AY16: =IF(ISBLANK(Lanes!AT16),"",ROUND(Lanes!AT16,2)) | AZ16: =IF(ISBLANK(Lanes!AP16),"",ROUND(Lanes!AU16,2)) | BA16: =IF(ISBLANK(Lanes!AP16),"",ROUND(Lanes!AV16,2)) | BB16: =IF(ISBLANK(Lanes!AW16),"",ROUND(Lanes!AW16,2)) | BC16: =IF(ISBLANK(Lanes!AX16),"",ROUND(Lanes!AX16,2)) | BD16: =IF(ISBLANK(Lanes!AY16),"",ROUND(Lanes!AY16,2)) | BE16: =IF(ISBLANK(Lanes!AX16),"",ROUND(Lanes!AZ16,2)) | BF16: =IF(ISBLANK(Lanes!BA16),"",ROUND(Lanes!BA16,2)) | BG16: =IF(ISBLANK(Lanes!BB16),"",ROUND(Lanes!BB16,2)) | BH16: =IF(ISBLANK(Lanes!AX16),"",ROUND(Lanes!BC16,2)) | BI16: =IF(ISBLANK(Lanes!AX16),"",ROUND(Lanes!BD16,2)) | BJ16: =IF(ISBLANK(Lanes!BE16),"",Lanes!BE16) | BK16: =IF(ISBLANK(Lanes!BF16),"",Lanes!BF16) | BL16: =IF(ISBLANK(Lanes!BG16),"",Lanes!BG16) | BM16: =IF(ISBLANK(Lanes!BH16),"",Lanes!BH16) | BN16: =IF(ISBLANK(Lanes!BI16),"",Lanes!BI16) | BO16: =IF(ISBLANK(Lanes!BJ16),"",Lanes!BJ16) | BP16: =IF(ISBLANK(Lanes!BK16),"",Lanes!BK16) | BQ16: =IF(ISBLANK(Lanes!BL16),"",Lanes!BL16) | BR16: =IF(ISBLANK(Lanes!BM16),"",ROUND(Lanes!BM16,0)) | BS16: =IF(ISBLANK(Lanes!BN16),"",ROUND(Lanes!BN16,0)) | BT16: =IF(ISBLANK(Lanes!BO16),"",ROUND(Lanes!BO16,0)) | BU16: =IF(ISBLANK(Lanes!BN16),"",ROUND(Lanes!BP16,0)) | BV16: =IF(ISBLANK(Lanes!BQ16),"",ROUND(Lanes!BQ16,1)) | BW16: =IF(ISBLANK(Lanes!BR16),"",Lanes!BR16) | BX16: =IF(ISBLANK(Lanes!BS16),"",Lanes!BS16) | BY16: =IF(ISBLANK(Lanes!BT16),"",Lanes!BT16) | BZ16: =IF(ISBLANK(Lanes!BU16),"",Lanes!BU16) | CA16: =IF(ISBLANK(Lanes!BV16),"",ROUND(Lanes!BV16,1)) | CB16: =IF(ISBLANK(Lanes!BW16),"",ROUND(Lanes!BW16,2)) | CC16: =IF(ISBLANK(Lanes!BX16),"",ROUND(Lanes!BX16,1)) | CD16: =IF(ISBLANK(Lanes!BY16),"",ROUND(Lanes!BY16,2)) | CE16: =IF(ISBLANK(Lanes!BZ16),"",ROUND(Lanes!BZ16,0)) | CF16: =IF(ISBLANK(Lanes!CA16),"",ROUND(Lanes!CA16,0)) | CG16: =IF(ISBLANK(Lanes!CB16),"",ROUND(Lanes!CB16,0)) | CH16: =IF(ISBLANK(Lanes!CC16),"",ROUND(Lanes!CC16,2)) | CI16: =IF(ISBLANK(Lanes!CD16),"",ROUND(Lanes!CD16,2)) | CJ16: =IF(ISBLANK(Lanes!CE16),"",ROUND(Lanes!CE16,2)) | CK16: =IF(ISBLANK(Lanes!CF16),"",ROUND(Lanes!CF16,0)) | CL16: =IF(ISBLANK(Lanes!CG16),"",ROUND(Lanes!CG16,0)) | CM16: =IF(ISBLANK(Lanes!CH16),"",ROUND(Lanes!CH16,0)) | CN16: =IF(ISBLANK(Lanes!CI16),"",ROUND(Lanes!CI16,2)) | CO16: =IF(ISBLANK(Lanes!CJ16),"",ROUND(Lanes!CJ16,2)) | CP16: =IF(ISBLANK(Lanes!CK16),"",ROUND(Lanes!CK16,2)) | CQ16: =IF(ISBLANK(Lanes!CL16),"","delete")
A17: 1421 | B17: 1106 | C17: 1 | D17: 116 | E17: 116 | F17: Existing | G17: Port to Port | H17: 40' RF | I17: Shanghai | J17: Shanghai | L17: China | M17: APAC | N17: Far East | O17: Tokyo | P17: Tokyo | R17: Japan | S17: APAC | T17: Far East | U17: Confectionary | V17: FOB | W17: Collect | X17: Receiving Unit | AA17: Yes | AB17: 138 | AC17: 3 | AD17: No | AE17: 0.25 | AF17: 0.25 | AG17: 0.25 | AH17: 0.25 | AI17: No | AJ17: 10 | AK17: 7 | AL17: 17 | AN17: 9 | AO17: 9 | AP17: 0 | AR17: 0.1 | AS17: USD | AT17: =IF(ISBLANK(Lanes!AO17),"",ROUND(Lanes!AO17,2)) | AU17: =IF(ISBLANK(Lanes!AP17),"",ROUND(Lanes!AP17,2)) | AV17: =IF(ISBLANK(Lanes!AQ17),"",ROUND(Lanes!AQ17,2)) | AW17: =IF(ISBLANK(Lanes!AP17),"",ROUND(Lanes!AR17,2)) | AX17: =IF(ISBLANK(Lanes!AS17),"",ROUND(Lanes!AS17,2)) | AY17: =IF(ISBLANK(Lanes!AT17),"",ROUND(Lanes!AT17,2)) | AZ17: =IF(ISBLANK(Lanes!AP17),"",ROUND(Lanes!AU17,2)) | BA17: =IF(ISBLANK(Lanes!AP17),"",ROUND(Lanes!AV17,2)) | BB17: =IF(ISBLANK(Lanes!AW17),"",ROUND(Lanes!AW17,2)) | BC17: =IF(ISBLANK(Lanes!AX17),"",ROUND(Lanes!AX17,2)) | BD17: =IF(ISBLANK(Lanes!AY17),"",ROUND(Lanes!AY17,2)) | BE17: =IF(ISBLANK(Lanes!AX17),"",ROUND(Lanes!AZ17,2)) | BF17: =IF(ISBLANK(Lanes!BA17),"",ROUND(Lanes!BA17,2)) | BG17: =IF(ISBLANK(Lanes!BB17),"",ROUND(Lanes!BB17,2)) | BH17: =IF(ISBLANK(Lanes!AX17),"",ROUND(Lanes!BC17,2)) | BI17: =IF(ISBLANK(Lanes!AX17),"",ROUND(Lanes!BD17,2)) | BJ17: =IF(ISBLANK(Lanes!BE17),"",Lanes!BE17) | BK17: =IF(ISBLANK(Lanes!BF17),"",Lanes!BF17) | BL17: =IF(ISBLANK(Lanes!BG17),"",Lanes!BG17) | BM17: =IF(ISBLANK(Lanes!BH17),"",Lanes!BH17) | BN17: =IF(ISBLANK(Lanes!BI17),"",Lanes!BI17) | BO17: =IF(ISBLANK(Lanes!BJ17),"",Lanes!BJ17) | BP17: =IF(ISBLANK(Lanes!BK17),"",Lanes!BK17) | BQ17: =IF(ISBLANK(Lanes!BL17),"",Lanes!BL17) | BR17: =IF(ISBLANK(Lanes!BM17),"",ROUND(Lanes!BM17,0)) | BS17: =IF(ISBLANK(Lanes!BN17),"",ROUND(Lanes!BN17,0)) | BT17: =IF(ISBLANK(Lanes!BO17),"",ROUND(Lanes!BO17,0)) | BU17: =IF(ISBLANK(Lanes!BN17),"",ROUND(Lanes!BP17,0)) | BV17: =IF(ISBLANK(Lanes!BQ17),"",ROUND(Lanes!BQ17,1)) | BW17: =IF(ISBLANK(Lanes!BR17),"",Lanes!BR17) | BX17: =IF(ISBLANK(Lanes!BS17),"",Lanes!BS17) | BY17: =IF(ISBLANK(Lanes!BT17),"",Lanes!BT17) | BZ17: =IF(ISBLANK(Lanes!BU17),"",Lanes!BU17) | CA17: =IF(ISBLANK(Lanes!BV17),"",ROUND(Lanes!BV17,1)) | CB17: =IF(ISBLANK(Lanes!BW17),"",ROUND(Lanes!BW17,2)) | CC17: =IF(ISBLANK(Lanes!BX17),"",ROUND(Lanes!BX17,1)) | CD17: =IF(ISBLANK(Lanes!BY17),"",ROUND(Lanes!BY17,2)) | CE17: =IF(ISBLANK(Lanes!BZ17),"",ROUND(Lanes!BZ17,0)) | CF17: =IF(ISBLANK(Lanes!CA17),"",ROUND(Lanes!CA17,0)) | CG17: =IF(ISBLANK(Lanes!CB17),"",ROUND(Lanes!CB17,0)) | CH17: =IF(ISBLANK(Lanes!CC17),"",ROUND(Lanes!CC17,2)) | CI17: =IF(ISBLANK(Lanes!CD17),"",ROUND(Lanes!CD17,2)) | CJ17: =IF(ISBLANK(Lanes!CE17),"",ROUND(Lanes!CE17,2)) | CK17: =IF(ISBLANK(Lanes!CF17),"",ROUND(Lanes!CF17,0)) | CL17: =IF(ISBLANK(Lanes!CG17),"",ROUND(Lanes!CG17,0)) | CM17: =IF(ISBLANK(Lanes!CH17),"",ROUND(Lanes!CH17,0)) | CN17: =IF(ISBLANK(Lanes!CI17),"",ROUND(Lanes!CI17,2)) | CO17: =IF(ISBLANK(Lanes!CJ17),"",ROUND(Lanes!CJ17,2)) | CP17: =IF(ISBLANK(Lanes!CK17),"",ROUND(Lanes!CK17,2)) | CQ17: =IF(ISBLANK(Lanes!CL17),"","delete")
A18: 1422 | B18: 1115 | C18: 1 | D18: 117 | E18: 117 | F18: Existing | G18: Port to Port | H18: 40' RF | I18: Xingang | J18: Tianjin | L18: China | M18: APAC | N18: Far East | O18: Bangkok (Pat/Lat Krabang/Laem Chabang) | P18: Bangkok (Pat/Lat Krabang/Laem Chabang) | R18: Thailand | S18: APAC | T18: Far East | U18: Confectionary | V18: FOB | W18: Collect | X18: Receiving Unit | AA18: Yes | AB18: 52 | AC18: 1 | AD18: No | AE18: 0.25 | AF18: 0.25 | AG18: 0.25 | AH18: 0.25 | AI18: No | AJ18: 10 | AK18: 7 | AL18: 17 | AM18: Food grade container | AN18: 10 | AO18: 7 | AP18: 17 | AR18: 0.1 | AS18: USD | AT18: =IF(ISBLANK(Lanes!AO18),"",ROUND(Lanes!AO18,2)) | AU18: =IF(ISBLANK(Lanes!AP18),"",ROUND(Lanes!AP18,2)) | AV18: =IF(ISBLANK(Lanes!AQ18),"",ROUND(Lanes!AQ18,2)) | AW18: =IF(ISBLANK(Lanes!AP18),"",ROUND(Lanes!AR18,2)) | AX18: =IF(ISBLANK(Lanes!AS18),"",ROUND(Lanes!AS18,2)) | AY18: =IF(ISBLANK(Lanes!AT18),"",ROUND(Lanes!AT18,2)) | AZ18: =IF(ISBLANK(Lanes!AP18),"",ROUND(Lanes!AU18,2)) | BA18: =IF(ISBLANK(Lanes!AP18),"",ROUND(Lanes!AV18,2)) | BB18: =IF(ISBLANK(Lanes!AW18),"",ROUND(Lanes!AW18,2)) | BC18: =IF(ISBLANK(Lanes!AX18),"",ROUND(Lanes!AX18,2)) | BD18: =IF(ISBLANK(Lanes!AY18),"",ROUND(Lanes!AY18,2)) | BE18: =IF(ISBLANK(Lanes!AX18),"",ROUND(Lanes!AZ18,2)) | BF18: =IF(ISBLANK(Lanes!BA18),"",ROUND(Lanes!BA18,2)) | BG18: =IF(ISBLANK(Lanes!BB18),"",ROUND(Lanes!BB18,2)) | BH18: =IF(ISBLANK(Lanes!AX18),"",ROUND(Lanes!BC18,2)) | BI18: =IF(ISBLANK(Lanes!AX18),"",ROUND(Lanes!BD18,2)) | BJ18: =IF(ISBLANK(Lanes!BE18),"",Lanes!BE18) | BK18: =IF(ISBLANK(Lanes!BF18),"",Lanes!BF18) | BL18: =IF(ISBLANK(Lanes!BG18),"",Lanes!BG18) | BM18: =IF(ISBLANK(Lanes!BH18),"",Lanes!BH18) | BN18: =IF(ISBLANK(Lanes!BI18),"",Lanes!BI18) | BO18: =IF(ISBLANK(Lanes!BJ18),"",Lanes!BJ18) | BP18: =IF(ISBLANK(Lanes!BK18),"",Lanes!BK18) | BQ18: =IF(ISBLANK(Lanes!BL18),"",Lanes!BL18) | BR18: =IF(ISBLANK(Lanes!BM18),"",ROUND(Lanes!BM18,0)) | BS18: =IF(ISBLANK(Lanes!BN18),"",ROUND(Lanes!BN18,0)) | BT18: =IF(ISBLANK(Lanes!BO18),"",ROUND(Lanes!BO18,0)) | BU18: =IF(ISBLANK(Lanes!BN18),"",ROUND(Lanes!BP18,0)) | BV18: =IF(ISBLANK(Lanes!BQ18),"",ROUND(Lanes!BQ18,1)) | BW18: =IF(ISBLANK(Lanes!BR18),"",Lanes!BR18) | BX18: =IF(ISBLANK(Lanes!BS18),"",Lanes!BS18) | BY18: =IF(ISBLANK(Lanes!BT18),"",Lanes!BT18) | BZ18: =IF(ISBLANK(Lanes!BU18),"",Lanes!BU18) | CA18: =IF(ISBLANK(Lanes!BV18),"",ROUND(Lanes!BV18,1)) | CB18: =IF(ISBLANK(Lanes!BW18),"",ROUND(Lanes!BW18,2)) | CC18: =IF(ISBLANK(Lanes!BX18),"",ROUND(Lanes!BX18,1)) | CD18: =IF(ISBLANK(Lanes!BY18),"",ROUND(Lanes!BY18,2)) | CE18: =IF(ISBLANK(Lanes!BZ18),"",ROUND(Lanes!BZ18,0)) | CF18: =IF(ISBLANK(Lanes!CA18),"",ROUND(Lanes!CA18,0)) | CG18: =IF(ISBLANK(Lanes!CB18),"",ROUND(Lanes!CB18,0)) | CH18: =IF(ISBLANK(Lanes!CC18),"",ROUND(Lanes!CC18,2)) | CI18: =IF(ISBLANK(Lanes!CD18),"",ROUND(Lanes!CD18,2)) | CJ18: =IF(ISBLANK(Lanes!CE18),"",ROUND(Lanes!CE18,2)) | CK18: =IF(ISBLANK(Lanes!CF18),"",ROUND(Lanes!CF18,0)) | CL18: =IF(ISBLANK(Lanes!CG18),"",ROUND(Lanes!CG18,0)) | CM18: =IF(ISBLANK(Lanes!CH18),"",ROUND(Lanes!CH18,0)) | CN18: =IF(ISBLANK(Lanes!CI18),"",ROUND(Lanes!CI18,2)) | CO18: =IF(ISBLANK(Lanes!CJ18),"",ROUND(Lanes!CJ18,2)) | CP18: =IF(ISBLANK(Lanes!CK18),"",ROUND(Lanes!CK18,2)) | CQ18: =IF(ISBLANK(Lanes!CL18),"","delete")
